2022-02-24 16:39:21,639 ERROR libqtile hook.py:fire():L392 Error in hook startup_once
Traceback (most recent call last):
  File "/usr/lib/python3.10/site-packages/libqtile/hook.py", line 390, in fire
    i(*args, **kwargs)
  File "/home/mk/.config/qtile/config.py", line 247, in start_once
    subprocess.call([home + '/.config/qtile/autostart.sh'])
  File "/usr/lib/python3.10/subprocess.py", line 345, in call
    with Popen(*popenargs, **kwargs) as p:
  File "/usr/lib/python3.10/subprocess.py", line 966, in __init__
    self._execute_child(args, executable, preexec_fn, close_fds,
  File "/usr/lib/python3.10/subprocess.py", line 1842, in _execute_child
    raise child_exception_type(errno_num, err_msg, err_filename)
PermissionError: [Errno 13] Permission denied: '/home/mk/.config/qtile/autostart.sh'
2022-02-24 16:43:22,537 WARNING libqtile lifecycle.py:_atexit():L38 Qtile will now terminate
2022-02-24 16:43:28,910 ERROR libqtile hook.py:fire():L392 Error in hook startup_once
Traceback (most recent call last):
  File "/usr/lib/python3.10/site-packages/libqtile/hook.py", line 390, in fire
    i(*args, **kwargs)
  File "/home/mk/.config/qtile/config.py", line 247, in start_once
    subprocess.call([home + '/.config/qtile/autostart.sh'])
  File "/usr/lib/python3.10/subprocess.py", line 345, in call
    with Popen(*popenargs, **kwargs) as p:
  File "/usr/lib/python3.10/subprocess.py", line 966, in __init__
    self._execute_child(args, executable, preexec_fn, close_fds,
  File "/usr/lib/python3.10/subprocess.py", line 1842, in _execute_child
    raise child_exception_type(errno_num, err_msg, err_filename)
PermissionError: [Errno 13] Permission denied: '/home/mk/.config/qtile/autostart.sh'
2022-02-24 16:46:04,506 ERROR libqtile manager.py:process_key_event():L390 KB command error kill: No object window in path 'window'
2022-02-24 16:46:05,314 ERROR libqtile manager.py:process_key_event():L390 KB command error kill: No object window in path 'window'
2022-02-24 16:46:05,479 ERROR libqtile manager.py:process_key_event():L390 KB command error kill: No object window in path 'window'
2022-02-24 16:46:05,630 ERROR libqtile manager.py:process_key_event():L390 KB command error kill: No object window in path 'window'
2022-02-24 16:46:28,767 WARNING libqtile lifecycle.py:_atexit():L38 Qtile will now terminate
2022-02-24 19:18:07,354 ERROR libqtile hook.py:fire():L392 Error in hook startup_once
Traceback (most recent call last):
  File "/usr/lib/python3.10/site-packages/libqtile/hook.py", line 390, in fire
    i(*args, **kwargs)
  File "/home/mk/.config/qtile/config.py", line 247, in start_once
    subprocess.call([home + '/.config/qtile/autostart.sh'])
  File "/usr/lib/python3.10/subprocess.py", line 345, in call
    with Popen(*popenargs, **kwargs) as p:
  File "/usr/lib/python3.10/subprocess.py", line 966, in __init__
    self._execute_child(args, executable, preexec_fn, close_fds,
  File "/usr/lib/python3.10/subprocess.py", line 1842, in _execute_child
    raise child_exception_type(errno_num, err_msg, err_filename)
PermissionError: [Errno 13] Permission denied: '/home/mk/.config/qtile/autostart.sh'
2022-02-24 20:00:25,395 ERROR libqtile manager.py:process_key_event():L390 KB command error right: No such command
2022-02-24 20:01:28,234 ERROR libqtile manager.py:cmd_reload_config():L258 Configuration error: name 'modkey' is not defined
2022-02-24 20:01:28,234 WARNING libqtile utils.py:send_notification():L242 dbus-next is not installed. Unable to send notifications.
2022-02-24 20:01:34,069 ERROR libqtile manager.py:cmd_reload_config():L258 Configuration error: name 'modkey' is not defined
2022-02-24 20:01:34,070 WARNING libqtile utils.py:send_notification():L242 dbus-next is not installed. Unable to send notifications.
2022-02-24 20:01:34,456 ERROR libqtile manager.py:cmd_reload_config():L258 Configuration error: name 'modkey' is not defined
2022-02-24 20:01:34,456 WARNING libqtile utils.py:send_notification():L242 dbus-next is not installed. Unable to send notifications.
2022-02-24 20:01:34,644 ERROR libqtile manager.py:cmd_reload_config():L258 Configuration error: name 'modkey' is not defined
2022-02-24 20:01:34,645 WARNING libqtile utils.py:send_notification():L242 dbus-next is not installed. Unable to send notifications.
2022-02-24 20:01:34,825 ERROR libqtile manager.py:cmd_reload_config():L258 Configuration error: name 'modkey' is not defined
2022-02-24 20:01:34,825 WARNING libqtile utils.py:send_notification():L242 dbus-next is not installed. Unable to send notifications.
2022-02-24 20:01:35,005 ERROR libqtile manager.py:cmd_reload_config():L258 Configuration error: name 'modkey' is not defined
2022-02-24 20:01:35,005 WARNING libqtile utils.py:send_notification():L242 dbus-next is not installed. Unable to send notifications.
2022-02-24 20:01:36,730 ERROR libqtile manager.py:process_key_event():L390 KB command error normalize: No such command
2022-02-24 20:01:37,225 ERROR libqtile manager.py:process_key_event():L390 KB command error normalize: No such command
2022-02-24 20:01:37,407 ERROR libqtile manager.py:process_key_event():L390 KB command error normalize: No such command
2022-02-24 20:01:38,576 ERROR libqtile manager.py:process_key_event():L390 KB command error right: No such command
2022-02-24 20:01:38,697 ERROR libqtile manager.py:process_key_event():L390 KB command error left: No such command
2022-02-24 20:01:39,405 ERROR libqtile manager.py:process_key_event():L390 KB command error left: No such command
2022-02-24 20:01:46,698 ERROR libqtile manager.py:process_key_event():L390 KB command error right: No such command
2022-02-24 20:02:33,619 ERROR libqtile manager.py:process_key_event():L390 KB command error normalize: No such command
2022-02-24 20:02:42,184 ERROR libqtile manager.py:process_key_event():L390 KB command error togroup: No object window in path 'window'
2022-02-24 20:03:03,159 ERROR libqtile manager.py:process_key_event():L390 KB command error normalize: No such command
2022-02-24 20:04:16,271 ERROR libqtile manager.py:cmd_reload_config():L258 Configuration error: name 'modkey' is not defined
2022-02-24 20:04:16,271 WARNING libqtile utils.py:send_notification():L242 dbus-next is not installed. Unable to send notifications.
2022-02-24 20:04:18,194 ERROR libqtile manager.py:cmd_reload_config():L258 Configuration error: name 'modkey' is not defined
2022-02-24 20:04:18,194 WARNING libqtile utils.py:send_notification():L242 dbus-next is not installed. Unable to send notifications.
2022-02-24 20:04:18,362 ERROR libqtile manager.py:cmd_reload_config():L258 Configuration error: name 'modkey' is not defined
2022-02-24 20:04:18,362 WARNING libqtile utils.py:send_notification():L242 dbus-next is not installed. Unable to send notifications.
2022-02-24 20:04:18,539 ERROR libqtile manager.py:cmd_reload_config():L258 Configuration error: name 'modkey' is not defined
2022-02-24 20:04:18,539 WARNING libqtile utils.py:send_notification():L242 dbus-next is not installed. Unable to send notifications.
2022-02-24 20:04:18,696 ERROR libqtile manager.py:cmd_reload_config():L258 Configuration error: name 'modkey' is not defined
2022-02-24 20:04:18,696 WARNING libqtile utils.py:send_notification():L242 dbus-next is not installed. Unable to send notifications.
2022-02-24 20:05:00,680 ERROR libqtile manager.py:cmd_reload_config():L258 Configuration error: name 'modkey' is not defined
2022-02-24 20:05:00,681 WARNING libqtile utils.py:send_notification():L242 dbus-next is not installed. Unable to send notifications.
2022-02-24 20:05:01,737 ERROR libqtile manager.py:cmd_reload_config():L258 Configuration error: name 'modkey' is not defined
2022-02-24 20:05:01,737 WARNING libqtile utils.py:send_notification():L242 dbus-next is not installed. Unable to send notifications.
2022-02-24 20:05:01,969 ERROR libqtile manager.py:cmd_reload_config():L258 Configuration error: name 'modkey' is not defined
2022-02-24 20:05:01,969 WARNING libqtile utils.py:send_notification():L242 dbus-next is not installed. Unable to send notifications.
2022-02-24 20:05:37,788 ERROR libqtile manager.py:cmd_reload_config():L258 Configuration error: name 'modkey' is not defined
2022-02-24 20:05:37,788 WARNING libqtile utils.py:send_notification():L242 dbus-next is not installed. Unable to send notifications.
2022-02-24 20:05:38,674 ERROR libqtile manager.py:cmd_reload_config():L258 Configuration error: name 'modkey' is not defined
2022-02-24 20:05:38,674 WARNING libqtile utils.py:send_notification():L242 dbus-next is not installed. Unable to send notifications.
2022-02-24 20:05:39,005 ERROR libqtile manager.py:cmd_reload_config():L258 Configuration error: name 'modkey' is not defined
2022-02-24 20:05:39,005 WARNING libqtile utils.py:send_notification():L242 dbus-next is not installed. Unable to send notifications.
2022-02-24 20:05:39,461 ERROR libqtile manager.py:cmd_reload_config():L258 Configuration error: name 'modkey' is not defined
2022-02-24 20:05:39,461 WARNING libqtile utils.py:send_notification():L242 dbus-next is not installed. Unable to send notifications.
2022-02-24 20:05:39,654 ERROR libqtile manager.py:cmd_reload_config():L258 Configuration error: name 'modkey' is not defined
2022-02-24 20:05:39,654 WARNING libqtile utils.py:send_notification():L242 dbus-next is not installed. Unable to send notifications.
2022-02-24 20:05:41,077 ERROR libqtile manager.py:cmd_reload_config():L258 Configuration error: name 'modkey' is not defined
2022-02-24 20:05:41,077 WARNING libqtile utils.py:send_notification():L242 dbus-next is not installed. Unable to send notifications.
2022-02-24 20:05:41,261 ERROR libqtile manager.py:cmd_reload_config():L258 Configuration error: name 'modkey' is not defined
2022-02-24 20:05:41,262 WARNING libqtile utils.py:send_notification():L242 dbus-next is not installed. Unable to send notifications.
2022-02-24 20:05:41,443 ERROR libqtile manager.py:cmd_reload_config():L258 Configuration error: name 'modkey' is not defined
2022-02-24 20:05:41,443 WARNING libqtile utils.py:send_notification():L242 dbus-next is not installed. Unable to send notifications.
2022-02-24 20:05:44,619 ERROR libqtile manager.py:cmd_reload_config():L258 Configuration error: name 'modkey' is not defined
2022-02-24 20:05:44,619 WARNING libqtile utils.py:send_notification():L242 dbus-next is not installed. Unable to send notifications.
2022-02-24 20:05:44,796 ERROR libqtile manager.py:cmd_reload_config():L258 Configuration error: name 'modkey' is not defined
2022-02-24 20:05:44,797 WARNING libqtile utils.py:send_notification():L242 dbus-next is not installed. Unable to send notifications.
2022-02-24 20:05:44,959 ERROR libqtile manager.py:cmd_reload_config():L258 Configuration error: name 'modkey' is not defined
2022-02-24 20:05:44,959 WARNING libqtile utils.py:send_notification():L242 dbus-next is not installed. Unable to send notifications.
2022-02-24 20:05:45,101 ERROR libqtile manager.py:cmd_reload_config():L258 Configuration error: name 'modkey' is not defined
2022-02-24 20:05:45,101 WARNING libqtile utils.py:send_notification():L242 dbus-next is not installed. Unable to send notifications.
2022-02-24 20:09:21,450 ERROR libqtile manager.py:cmd_reload_config():L258 Configuration error: name 'modkey' is not defined
2022-02-24 20:09:21,450 WARNING libqtile utils.py:send_notification():L242 dbus-next is not installed. Unable to send notifications.
2022-02-24 20:09:21,991 ERROR libqtile manager.py:cmd_reload_config():L258 Configuration error: name 'modkey' is not defined
2022-02-24 20:09:21,991 WARNING libqtile utils.py:send_notification():L242 dbus-next is not installed. Unable to send notifications.
2022-02-24 20:09:22,171 ERROR libqtile manager.py:cmd_reload_config():L258 Configuration error: name 'modkey' is not defined
2022-02-24 20:09:22,171 WARNING libqtile utils.py:send_notification():L242 dbus-next is not installed. Unable to send notifications.
2022-02-24 20:09:22,327 ERROR libqtile manager.py:cmd_reload_config():L258 Configuration error: name 'modkey' is not defined
2022-02-24 20:09:22,327 WARNING libqtile utils.py:send_notification():L242 dbus-next is not installed. Unable to send notifications.
2022-02-24 20:13:29,623 ERROR libqtile manager.py:process_key_event():L390 KB command error normalize: No such command
2022-02-24 20:13:30,921 ERROR libqtile manager.py:process_key_event():L390 KB command error maximize: No such command
2022-02-24 20:13:31,984 ERROR libqtile manager.py:process_key_event():L390 KB command error maximize: No such command
2022-02-24 20:13:32,152 ERROR libqtile manager.py:process_key_event():L390 KB command error maximize: No such command
2022-02-24 20:13:32,310 ERROR libqtile manager.py:process_key_event():L390 KB command error maximize: No such command
2022-02-24 20:13:32,467 ERROR libqtile manager.py:process_key_event():L390 KB command error maximize: No such command
2022-02-24 20:13:39,341 ERROR libqtile manager.py:process_key_event():L390 KB command error maximize: No such command
2022-02-24 20:13:40,057 ERROR libqtile manager.py:process_key_event():L390 KB command error normalize: No such command
2022-02-24 20:13:41,079 ERROR libqtile manager.py:process_key_event():L390 KB command error maximize: No such command
2022-02-24 20:13:41,343 ERROR libqtile manager.py:process_key_event():L390 KB command error normalize: No such command
2022-02-24 20:13:41,602 ERROR libqtile manager.py:process_key_event():L390 KB command error maximize: No such command
2022-02-24 20:13:41,836 ERROR libqtile manager.py:process_key_event():L390 KB command error normalize: No such command
2022-02-24 20:13:42,100 ERROR libqtile manager.py:process_key_event():L390 KB command error maximize: No such command
2022-02-24 20:13:42,350 ERROR libqtile manager.py:process_key_event():L390 KB command error normalize: No such command
2022-02-24 20:16:15,670 ERROR libqtile manager.py:cmd_reload_config():L258 Configuration error: Match.__init__() got an unexpected keyword argument 'wm_Class'
2022-02-24 20:16:15,670 WARNING libqtile utils.py:send_notification():L242 dbus-next is not installed. Unable to send notifications.
2022-02-24 20:16:16,333 ERROR libqtile manager.py:cmd_reload_config():L258 Configuration error: Match.__init__() got an unexpected keyword argument 'wm_Class'
2022-02-24 20:16:16,333 WARNING libqtile utils.py:send_notification():L242 dbus-next is not installed. Unable to send notifications.
2022-02-24 20:16:16,542 ERROR libqtile manager.py:cmd_reload_config():L258 Configuration error: Match.__init__() got an unexpected keyword argument 'wm_Class'
2022-02-24 20:16:16,542 WARNING libqtile utils.py:send_notification():L242 dbus-next is not installed. Unable to send notifications.
2022-02-24 20:16:16,769 ERROR libqtile manager.py:cmd_reload_config():L258 Configuration error: Match.__init__() got an unexpected keyword argument 'wm_Class'
2022-02-24 20:16:16,769 WARNING libqtile utils.py:send_notification():L242 dbus-next is not installed. Unable to send notifications.
2022-02-24 20:26:53,629 ERROR libqtile manager.py:process_button_click():L708 Mouse command error get_position: No object window in path 'window'
2022-02-24 20:27:45,855 ERROR libqtile core.py:_xpoll():L331 Got an exception in poll loop
Traceback (most recent call last):
  File "/usr/lib/python3.10/site-packages/libqtile/backend/x11/core.py", line 299, in _xpoll
    ret = target(event)
  File "/usr/lib/python3.10/site-packages/libqtile/backend/x11/window.py", line 1137, in handle_KeyPress
    self.process_key_press(keysym)
  File "/usr/lib/python3.10/site-packages/libqtile/bar.py", line 508, in process_key_press
    if self.has_keyboard:
  File "/usr/lib/python3.10/site-packages/libqtile/configurable.py", line 49, in __getattr__
    raise AttributeError("%s has no attribute: %s" % (cname, name))
AttributeError: Bar has no attribute: has_keyboard
2022-02-25 06:17:11,427 ERROR libqtile core.py:_xpoll():L331 Got an exception in poll loop
Traceback (most recent call last):
  File "/usr/lib/python3.10/site-packages/libqtile/backend/x11/core.py", line 299, in _xpoll
    ret = target(event)
  File "/usr/lib/python3.10/site-packages/libqtile/backend/x11/core.py", line 722, in handle_UnmapNotify
    self.qtile.unmanage(event.window)
  File "/usr/lib/python3.10/site-packages/libqtile/core/manager.py", line 618, in unmanage
    c.group.remove(c)
  File "/usr/lib/python3.10/site-packages/libqtile/group.py", line 288, in remove
    self.tiled_windows.remove(win)
KeyError: Window(name='masterduel', wid=96468993)
2022-02-25 06:17:12,429 ERROR libqtile loop.py:_handle_exception():L61 Window(name='masterduel', wid=96468993)
Traceback (most recent call last):
  File "/usr/lib/python3.10/asyncio/events.py", line 80, in _run
    self._context.run(self._callback, *self._args)
  File "/usr/lib/python3.10/site-packages/libqtile/core/manager.py", line 843, in f
    func(*args)
  File "/usr/lib/python3.10/site-packages/libqtile/dgroups.py", line 249, in delete_client
    del self.timeout[client]
KeyError: Window(name='masterduel', wid=96468993)
2022-02-25 06:17:23,970 ERROR libqtile core.py:get_interesting_pid():L806 Got an exception in getting the window pid
Traceback (most recent call last):
  File "/usr/lib/python3.10/site-packages/xcffib/__init__.py", line 571, in wrapper
    return f(*args)
  File "/usr/lib/python3.10/site-packages/xcffib/__init__.py", line 658, in wait_for_reply
    self._process_error(error_p[0])
  File "/usr/lib/python3.10/site-packages/xcffib/__init__.py", line 645, in _process_error
    self.invalid()
  File "/usr/lib/python3.10/site-packages/xcffib/__init__.py", line 559, in invalid
    raise ConnectionException(err)
xcffib.ConnectionException: xcb connection errors because of socket, pipe and other stream errors.

During handling of the above exception, another exception occurred:

Traceback (most recent call last):
  File "/usr/lib/python3.10/site-packages/libqtile/backend/x11/core.py", line 804, in get_interesting_pid
    return win.window.get_net_wm_pid()
  File "/usr/lib/python3.10/site-packages/libqtile/backend/x11/window.py", line 293, in get_net_wm_pid
    r = self.get_property("_NET_WM_PID", unpack=int)
  File "/usr/lib/python3.10/site-packages/libqtile/backend/x11/window.py", line 381, in get_property
    ).reply()
  File "/usr/lib/python3.10/site-packages/xcffib/__init__.py", line 332, in reply
    data = self.conn.wait_for_reply(self.sequence)
  File "/usr/lib/python3.10/site-packages/xcffib/__init__.py", line 573, in wrapper
    self.invalid()
  File "/usr/lib/python3.10/site-packages/xcffib/__init__.py", line 559, in invalid
    raise ConnectionException(err)
xcffib.ConnectionException: xcb connection errors because of socket, pipe and other stream errors.
2022-02-25 06:17:23,970 ERROR libqtile core.py:get_interesting_pid():L806 Got an exception in getting the window pid
Traceback (most recent call last):
  File "/usr/lib/python3.10/site-packages/libqtile/backend/x11/core.py", line 804, in get_interesting_pid
    return win.window.get_net_wm_pid()
  File "/usr/lib/python3.10/site-packages/libqtile/backend/x11/window.py", line 293, in get_net_wm_pid
    r = self.get_property("_NET_WM_PID", unpack=int)
  File "/usr/lib/python3.10/site-packages/libqtile/backend/x11/window.py", line 374, in get_property
    r = self.conn.conn.core.GetProperty(
  File "/usr/lib/python3.10/site-packages/xcffib/xproto.py", line 2720, in GetProperty
    return self.send_request(20, buf, GetPropertyCookie, is_checked=is_checked)
  File "/usr/lib/python3.10/site-packages/xcffib/__init__.py", line 391, in send_request
    seq = self.conn.send_request(flags, xcb_parts + 2, xcb_req)
  File "/usr/lib/python3.10/site-packages/xcffib/__init__.py", line 569, in wrapper
    self.invalid()
  File "/usr/lib/python3.10/site-packages/xcffib/__init__.py", line 559, in invalid
    raise ConnectionException(err)
xcffib.ConnectionException: xcb connection errors because of socket, pipe and other stream errors.
2022-02-25 06:17:23,971 ERROR libqtile manager.py:_finalize_configurables():L293 exception during finalize
Traceback (most recent call last):
  File "/usr/lib/python3.10/site-packages/libqtile/core/manager.py", line 281, in _finalize_configurables
    widget.finalize()
  File "/usr/lib/python3.10/site-packages/libqtile/widget/base.py", line 232, in finalize
    self.drawer.finalize()
  File "/usr/lib/python3.10/site-packages/libqtile/backend/x11/drawer.py", line 37, in finalize
    self._free_pixmap()
  File "/usr/lib/python3.10/site-packages/libqtile/backend/x11/drawer.py", line 117, in _free_pixmap
    self.qtile.core.conn.conn.core.FreePixmap(self._pixmap)
  File "/usr/lib/python3.10/site-packages/xcffib/xproto.py", line 2863, in FreePixmap
    return self.send_request(54, buf, is_checked=is_checked)
  File "/usr/lib/python3.10/site-packages/xcffib/__init__.py", line 391, in send_request
    seq = self.conn.send_request(flags, xcb_parts + 2, xcb_req)
  File "/usr/lib/python3.10/site-packages/xcffib/__init__.py", line 569, in wrapper
    self.invalid()
  File "/usr/lib/python3.10/site-packages/xcffib/__init__.py", line 559, in invalid
    raise ConnectionException(err)
xcffib.ConnectionException: xcb connection errors because of socket, pipe and other stream errors.
2022-02-25 06:17:23,971 ERROR libqtile core.py:_xpoll():L323 Shutting down due to X connection error XCB_CONN_ERROR (1)
Traceback (most recent call last):
  File "/usr/lib/python3.10/site-packages/libqtile/backend/x11/core.py", line 285, in _xpoll
    event = self.conn.conn.poll_for_event()
  File "/usr/lib/python3.10/site-packages/xcffib/__init__.py", line 569, in wrapper
    self.invalid()
  File "/usr/lib/python3.10/site-packages/xcffib/__init__.py", line 559, in invalid
    raise ConnectionException(err)
xcffib.ConnectionException: xcb connection errors because of socket, pipe and other stream errors.
2022-02-25 06:17:23,972 ERROR libqtile core.py:get_interesting_pid():L806 Got an exception in getting the window pid
Traceback (most recent call last):
  File "/usr/lib/python3.10/site-packages/libqtile/backend/x11/core.py", line 285, in _xpoll
    event = self.conn.conn.poll_for_event()
  File "/usr/lib/python3.10/site-packages/xcffib/__init__.py", line 569, in wrapper
    self.invalid()
  File "/usr/lib/python3.10/site-packages/xcffib/__init__.py", line 559, in invalid
    raise ConnectionException(err)
xcffib.ConnectionException: xcb connection errors because of socket, pipe and other stream errors.

During handling of the above exception, another exception occurred:

Traceback (most recent call last):
  File "/usr/lib/python3.10/site-packages/libqtile/backend/x11/core.py", line 804, in get_interesting_pid
    return win.window.get_net_wm_pid()
  File "/usr/lib/python3.10/site-packages/libqtile/backend/x11/window.py", line 293, in get_net_wm_pid
    r = self.get_property("_NET_WM_PID", unpack=int)
  File "/usr/lib/python3.10/site-packages/libqtile/backend/x11/window.py", line 374, in get_property
    r = self.conn.conn.core.GetProperty(
  File "/usr/lib/python3.10/site-packages/xcffib/xproto.py", line 2720, in GetProperty
    return self.send_request(20, buf, GetPropertyCookie, is_checked=is_checked)
  File "/usr/lib/python3.10/site-packages/xcffib/__init__.py", line 391, in send_request
    seq = self.conn.send_request(flags, xcb_parts + 2, xcb_req)
  File "/usr/lib/python3.10/site-packages/xcffib/__init__.py", line 569, in wrapper
    self.invalid()
  File "/usr/lib/python3.10/site-packages/xcffib/__init__.py", line 559, in invalid
    raise ConnectionException(err)
xcffib.ConnectionException: xcb connection errors because of socket, pipe and other stream errors.
2022-02-25 06:17:23,972 ERROR libqtile core.py:get_interesting_pid():L806 Got an exception in getting the window pid
Traceback (most recent call last):
  File "/usr/lib/python3.10/site-packages/libqtile/backend/x11/core.py", line 804, in get_interesting_pid
    return win.window.get_net_wm_pid()
  File "/usr/lib/python3.10/site-packages/libqtile/backend/x11/window.py", line 293, in get_net_wm_pid
    r = self.get_property("_NET_WM_PID", unpack=int)
  File "/usr/lib/python3.10/site-packages/libqtile/backend/x11/window.py", line 374, in get_property
    r = self.conn.conn.core.GetProperty(
  File "/usr/lib/python3.10/site-packages/xcffib/xproto.py", line 2720, in GetProperty
    return self.send_request(20, buf, GetPropertyCookie, is_checked=is_checked)
  File "/usr/lib/python3.10/site-packages/xcffib/__init__.py", line 391, in send_request
    seq = self.conn.send_request(flags, xcb_parts + 2, xcb_req)
  File "/usr/lib/python3.10/site-packages/xcffib/__init__.py", line 569, in wrapper
    self.invalid()
  File "/usr/lib/python3.10/site-packages/xcffib/__init__.py", line 559, in invalid
    raise ConnectionException(err)
xcffib.ConnectionException: xcb connection errors because of socket, pipe and other stream errors.
2022-02-25 06:17:23,973 ERROR libqtile start.py:start():L94 Qtile crashed
Traceback (most recent call last):
  File "/usr/lib/python3.10/site-packages/libqtile/scripts/start.py", line 92, in start
    q.loop()
  File "/usr/lib/python3.10/site-packages/libqtile/core/manager.py", line 190, in loop
    asyncio.run(self.async_loop())
  File "/usr/lib/python3.10/asyncio/runners.py", line 44, in run
    return loop.run_until_complete(main)
  File "/usr/lib/python3.10/asyncio/base_events.py", line 641, in run_until_complete
    return future.result()
  File "/usr/lib/python3.10/site-packages/libqtile/core/manager.py", line 218, in async_loop
    self.finalize()
  File "/usr/lib/python3.10/site-packages/libqtile/core/manager.py", line 298, in finalize
    self.core.finalize()
  File "/usr/lib/python3.10/site-packages/libqtile/backend/x11/core.py", line 161, in finalize
    self.conn.conn.core.DeletePropertyChecked(
  File "/usr/lib/python3.10/site-packages/xcffib/xproto.py", line 2716, in DeleteProperty
    return self.send_request(19, buf, is_checked=is_checked)
  File "/usr/lib/python3.10/site-packages/xcffib/__init__.py", line 391, in send_request
    seq = self.conn.send_request(flags, xcb_parts + 2, xcb_req)
  File "/usr/lib/python3.10/site-packages/xcffib/__init__.py", line 569, in wrapper
    self.invalid()
  File "/usr/lib/python3.10/site-packages/xcffib/__init__.py", line 559, in invalid
    raise ConnectionException(err)
xcffib.ConnectionException: xcb connection errors because of socket, pipe and other stream errors.
2022-02-25 06:17:23,973 WARNING libqtile lifecycle.py:_atexit():L38 Qtile will now terminate
2022-02-25 09:51:27,099 ERROR libqtile hook.py:fire():L392 Error in hook startup_once
Traceback (most recent call last):
  File "/usr/lib/python3.10/site-packages/libqtile/hook.py", line 390, in fire
    i(*args, **kwargs)
  File "/home/mk/.config/qtile/config.py", line 252, in start_once
    subprocess.call([home + '/.config/qtile/autostart.sh'])
  File "/usr/lib/python3.10/subprocess.py", line 345, in call
    with Popen(*popenargs, **kwargs) as p:
  File "/usr/lib/python3.10/subprocess.py", line 966, in __init__
    self._execute_child(args, executable, preexec_fn, close_fds,
  File "/usr/lib/python3.10/subprocess.py", line 1842, in _execute_child
    raise child_exception_type(errno_num, err_msg, err_filename)
PermissionError: [Errno 13] Permission denied: '/home/mk/.config/qtile/autostart.sh'
2022-02-25 10:10:57,156 ERROR libqtile manager.py:cmd_reload_config():L258 Configuration error: name 'matches' is not defined
2022-02-25 10:10:57,156 WARNING libqtile utils.py:send_notification():L242 dbus-next is not installed. Unable to send notifications.
2022-02-25 10:10:57,718 ERROR libqtile manager.py:cmd_reload_config():L258 Configuration error: name 'matches' is not defined
2022-02-25 10:10:57,718 WARNING libqtile utils.py:send_notification():L242 dbus-next is not installed. Unable to send notifications.
2022-02-25 10:10:57,898 ERROR libqtile manager.py:cmd_reload_config():L258 Configuration error: name 'matches' is not defined
2022-02-25 10:10:57,898 WARNING libqtile utils.py:send_notification():L242 dbus-next is not installed. Unable to send notifications.
2022-02-25 13:34:10,870 ERROR libqtile base.py:_wrapper():L345 got exception from widget timer
Traceback (most recent call last):
  File "/usr/lib/python3.10/site-packages/libqtile/widget/base.py", line 343, in _wrapper
    method(*method_args)
  File "/usr/lib/python3.10/site-packages/libqtile/widget/volume.py", line 126, in update
    vol = self.get_volume()
  File "/usr/lib/python3.10/site-packages/libqtile/widget/volume.py", line 188, in get_volume
    mixer_out = self.call_process(get_volume_cmd)
  File "/usr/lib/python3.10/site-packages/libqtile/widget/base.py", line 330, in call_process
    return subprocess.check_output(command, **kwargs, encoding="utf-8")
  File "/usr/lib/python3.10/subprocess.py", line 420, in check_output
    return run(*popenargs, stdout=PIPE, timeout=timeout, check=True,
  File "/usr/lib/python3.10/subprocess.py", line 501, in run
    with Popen(*popenargs, **kwargs) as process:
  File "/usr/lib/python3.10/subprocess.py", line 966, in __init__
    self._execute_child(args, executable, preexec_fn, close_fds,
  File "/usr/lib/python3.10/subprocess.py", line 1842, in _execute_child
    raise child_exception_type(errno_num, err_msg, err_filename)
FileNotFoundError: [Errno 2] No such file or directory: 'amixer'
2022-02-25 13:35:23,357 ERROR libqtile base.py:_wrapper():L345 got exception from widget timer
Traceback (most recent call last):
  File "/usr/lib/python3.10/site-packages/libqtile/widget/base.py", line 343, in _wrapper
    method(*method_args)
  File "/usr/lib/python3.10/site-packages/libqtile/widget/volume.py", line 126, in update
    vol = self.get_volume()
  File "/usr/lib/python3.10/site-packages/libqtile/widget/volume.py", line 188, in get_volume
    mixer_out = self.call_process(get_volume_cmd)
  File "/usr/lib/python3.10/site-packages/libqtile/widget/base.py", line 330, in call_process
    return subprocess.check_output(command, **kwargs, encoding="utf-8")
  File "/usr/lib/python3.10/subprocess.py", line 420, in check_output
    return run(*popenargs, stdout=PIPE, timeout=timeout, check=True,
  File "/usr/lib/python3.10/subprocess.py", line 501, in run
    with Popen(*popenargs, **kwargs) as process:
  File "/usr/lib/python3.10/subprocess.py", line 966, in __init__
    self._execute_child(args, executable, preexec_fn, close_fds,
  File "/usr/lib/python3.10/subprocess.py", line 1842, in _execute_child
    raise child_exception_type(errno_num, err_msg, err_filename)
FileNotFoundError: [Errno 2] No such file or directory: 'amixer'
2022-02-25 13:36:51,110 ERROR libqtile base.py:_wrapper():L345 got exception from widget timer
Traceback (most recent call last):
  File "/usr/lib/python3.10/site-packages/libqtile/widget/base.py", line 343, in _wrapper
    method(*method_args)
  File "/usr/lib/python3.10/site-packages/libqtile/widget/volume.py", line 126, in update
    vol = self.get_volume()
  File "/usr/lib/python3.10/site-packages/libqtile/widget/volume.py", line 188, in get_volume
    mixer_out = self.call_process(get_volume_cmd)
  File "/usr/lib/python3.10/site-packages/libqtile/widget/base.py", line 330, in call_process
    return subprocess.check_output(command, **kwargs, encoding="utf-8")
  File "/usr/lib/python3.10/subprocess.py", line 420, in check_output
    return run(*popenargs, stdout=PIPE, timeout=timeout, check=True,
  File "/usr/lib/python3.10/subprocess.py", line 501, in run
    with Popen(*popenargs, **kwargs) as process:
  File "/usr/lib/python3.10/subprocess.py", line 966, in __init__
    self._execute_child(args, executable, preexec_fn, close_fds,
  File "/usr/lib/python3.10/subprocess.py", line 1842, in _execute_child
    raise child_exception_type(errno_num, err_msg, err_filename)
FileNotFoundError: [Errno 2] No such file or directory: 'amixer'
2022-02-25 13:46:38,723 ERROR libqtile core.py:_xpoll():L331 Got an exception in poll loop
Traceback (most recent call last):
  File "/usr/lib/python3.10/site-packages/libqtile/backend/x11/core.py", line 299, in _xpoll
    ret = target(event)
  File "/usr/lib/python3.10/site-packages/libqtile/backend/x11/window.py", line 1119, in handle_ButtonPress
    self.process_button_click(e.event_x, e.event_y, e.detail)
  File "/usr/lib/python3.10/site-packages/libqtile/bar.py", line 462, in process_button_click
    widget.button_press(
  File "/usr/lib/python3.10/site-packages/libqtile/widget/volume.py", line 122, in button_press
    base._TextBox.button_press(self, x, y, button)
  File "/usr/lib/python3.10/site-packages/libqtile/widget/base.py", line 264, in button_press
    cmd()
  File "/usr/lib/python3.10/site-packages/libqtile/widget/volume.py", line 212, in cmd_increase_vol
    subprocess.call(
  File "/usr/lib/python3.10/subprocess.py", line 345, in call
    with Popen(*popenargs, **kwargs) as p:
  File "/usr/lib/python3.10/subprocess.py", line 966, in __init__
    self._execute_child(args, executable, preexec_fn, close_fds,
  File "/usr/lib/python3.10/subprocess.py", line 1842, in _execute_child
    raise child_exception_type(errno_num, err_msg, err_filename)
FileNotFoundError: [Errno 2] No such file or directory: 'amixer'
2022-02-25 13:46:38,766 ERROR libqtile core.py:_xpoll():L331 Got an exception in poll loop
Traceback (most recent call last):
  File "/usr/lib/python3.10/site-packages/libqtile/backend/x11/core.py", line 299, in _xpoll
    ret = target(event)
  File "/usr/lib/python3.10/site-packages/libqtile/backend/x11/window.py", line 1119, in handle_ButtonPress
    self.process_button_click(e.event_x, e.event_y, e.detail)
  File "/usr/lib/python3.10/site-packages/libqtile/bar.py", line 462, in process_button_click
    widget.button_press(
  File "/usr/lib/python3.10/site-packages/libqtile/widget/volume.py", line 122, in button_press
    base._TextBox.button_press(self, x, y, button)
  File "/usr/lib/python3.10/site-packages/libqtile/widget/base.py", line 264, in button_press
    cmd()
  File "/usr/lib/python3.10/site-packages/libqtile/widget/volume.py", line 212, in cmd_increase_vol
    subprocess.call(
  File "/usr/lib/python3.10/subprocess.py", line 345, in call
    with Popen(*popenargs, **kwargs) as p:
  File "/usr/lib/python3.10/subprocess.py", line 966, in __init__
    self._execute_child(args, executable, preexec_fn, close_fds,
  File "/usr/lib/python3.10/subprocess.py", line 1842, in _execute_child
    raise child_exception_type(errno_num, err_msg, err_filename)
FileNotFoundError: [Errno 2] No such file or directory: 'amixer'
2022-02-25 13:46:39,338 ERROR libqtile core.py:_xpoll():L331 Got an exception in poll loop
Traceback (most recent call last):
  File "/usr/lib/python3.10/site-packages/libqtile/backend/x11/core.py", line 299, in _xpoll
    ret = target(event)
  File "/usr/lib/python3.10/site-packages/libqtile/backend/x11/window.py", line 1119, in handle_ButtonPress
    self.process_button_click(e.event_x, e.event_y, e.detail)
  File "/usr/lib/python3.10/site-packages/libqtile/bar.py", line 462, in process_button_click
    widget.button_press(
  File "/usr/lib/python3.10/site-packages/libqtile/widget/volume.py", line 122, in button_press
    base._TextBox.button_press(self, x, y, button)
  File "/usr/lib/python3.10/site-packages/libqtile/widget/base.py", line 264, in button_press
    cmd()
  File "/usr/lib/python3.10/site-packages/libqtile/widget/volume.py", line 228, in cmd_mute
    subprocess.call(self.create_amixer_command("-q", "sset", self.channel, "toggle"))
  File "/usr/lib/python3.10/subprocess.py", line 345, in call
    with Popen(*popenargs, **kwargs) as p:
  File "/usr/lib/python3.10/subprocess.py", line 966, in __init__
    self._execute_child(args, executable, preexec_fn, close_fds,
  File "/usr/lib/python3.10/subprocess.py", line 1842, in _execute_child
    raise child_exception_type(errno_num, err_msg, err_filename)
FileNotFoundError: [Errno 2] No such file or directory: 'amixer'
2022-02-25 13:46:40,094 ERROR libqtile core.py:_xpoll():L331 Got an exception in poll loop
Traceback (most recent call last):
  File "/usr/lib/python3.10/site-packages/libqtile/backend/x11/core.py", line 299, in _xpoll
    ret = target(event)
  File "/usr/lib/python3.10/site-packages/libqtile/backend/x11/window.py", line 1119, in handle_ButtonPress
    self.process_button_click(e.event_x, e.event_y, e.detail)
  File "/usr/lib/python3.10/site-packages/libqtile/bar.py", line 462, in process_button_click
    widget.button_press(
  File "/usr/lib/python3.10/site-packages/libqtile/widget/volume.py", line 122, in button_press
    base._TextBox.button_press(self, x, y, button)
  File "/usr/lib/python3.10/site-packages/libqtile/widget/base.py", line 264, in button_press
    cmd()
  File "/usr/lib/python3.10/site-packages/libqtile/widget/volume.py", line 220, in cmd_decrease_vol
    subprocess.call(
  File "/usr/lib/python3.10/subprocess.py", line 345, in call
    with Popen(*popenargs, **kwargs) as p:
  File "/usr/lib/python3.10/subprocess.py", line 966, in __init__
    self._execute_child(args, executable, preexec_fn, close_fds,
  File "/usr/lib/python3.10/subprocess.py", line 1842, in _execute_child
    raise child_exception_type(errno_num, err_msg, err_filename)
FileNotFoundError: [Errno 2] No such file or directory: 'amixer'
2022-02-25 13:46:40,114 ERROR libqtile core.py:_xpoll():L331 Got an exception in poll loop
Traceback (most recent call last):
  File "/usr/lib/python3.10/site-packages/libqtile/backend/x11/core.py", line 299, in _xpoll
    ret = target(event)
  File "/usr/lib/python3.10/site-packages/libqtile/backend/x11/window.py", line 1119, in handle_ButtonPress
    self.process_button_click(e.event_x, e.event_y, e.detail)
  File "/usr/lib/python3.10/site-packages/libqtile/bar.py", line 462, in process_button_click
    widget.button_press(
  File "/usr/lib/python3.10/site-packages/libqtile/widget/volume.py", line 122, in button_press
    base._TextBox.button_press(self, x, y, button)
  File "/usr/lib/python3.10/site-packages/libqtile/widget/base.py", line 264, in button_press
    cmd()
  File "/usr/lib/python3.10/site-packages/libqtile/widget/volume.py", line 220, in cmd_decrease_vol
    subprocess.call(
  File "/usr/lib/python3.10/subprocess.py", line 345, in call
    with Popen(*popenargs, **kwargs) as p:
  File "/usr/lib/python3.10/subprocess.py", line 966, in __init__
    self._execute_child(args, executable, preexec_fn, close_fds,
  File "/usr/lib/python3.10/subprocess.py", line 1842, in _execute_child
    raise child_exception_type(errno_num, err_msg, err_filename)
FileNotFoundError: [Errno 2] No such file or directory: 'amixer'
2022-02-25 13:46:40,135 ERROR libqtile core.py:_xpoll():L331 Got an exception in poll loop
Traceback (most recent call last):
  File "/usr/lib/python3.10/site-packages/libqtile/backend/x11/core.py", line 299, in _xpoll
    ret = target(event)
  File "/usr/lib/python3.10/site-packages/libqtile/backend/x11/window.py", line 1119, in handle_ButtonPress
    self.process_button_click(e.event_x, e.event_y, e.detail)
  File "/usr/lib/python3.10/site-packages/libqtile/bar.py", line 462, in process_button_click
    widget.button_press(
  File "/usr/lib/python3.10/site-packages/libqtile/widget/volume.py", line 122, in button_press
    base._TextBox.button_press(self, x, y, button)
  File "/usr/lib/python3.10/site-packages/libqtile/widget/base.py", line 264, in button_press
    cmd()
  File "/usr/lib/python3.10/site-packages/libqtile/widget/volume.py", line 220, in cmd_decrease_vol
    subprocess.call(
  File "/usr/lib/python3.10/subprocess.py", line 345, in call
    with Popen(*popenargs, **kwargs) as p:
  File "/usr/lib/python3.10/subprocess.py", line 966, in __init__
    self._execute_child(args, executable, preexec_fn, close_fds,
  File "/usr/lib/python3.10/subprocess.py", line 1842, in _execute_child
    raise child_exception_type(errno_num, err_msg, err_filename)
FileNotFoundError: [Errno 2] No such file or directory: 'amixer'
2022-02-25 13:46:40,159 ERROR libqtile core.py:_xpoll():L331 Got an exception in poll loop
Traceback (most recent call last):
  File "/usr/lib/python3.10/site-packages/libqtile/backend/x11/core.py", line 299, in _xpoll
    ret = target(event)
  File "/usr/lib/python3.10/site-packages/libqtile/backend/x11/window.py", line 1119, in handle_ButtonPress
    self.process_button_click(e.event_x, e.event_y, e.detail)
  File "/usr/lib/python3.10/site-packages/libqtile/bar.py", line 462, in process_button_click
    widget.button_press(
  File "/usr/lib/python3.10/site-packages/libqtile/widget/volume.py", line 122, in button_press
    base._TextBox.button_press(self, x, y, button)
  File "/usr/lib/python3.10/site-packages/libqtile/widget/base.py", line 264, in button_press
    cmd()
  File "/usr/lib/python3.10/site-packages/libqtile/widget/volume.py", line 220, in cmd_decrease_vol
    subprocess.call(
  File "/usr/lib/python3.10/subprocess.py", line 345, in call
    with Popen(*popenargs, **kwargs) as p:
  File "/usr/lib/python3.10/subprocess.py", line 966, in __init__
    self._execute_child(args, executable, preexec_fn, close_fds,
  File "/usr/lib/python3.10/subprocess.py", line 1842, in _execute_child
    raise child_exception_type(errno_num, err_msg, err_filename)
FileNotFoundError: [Errno 2] No such file or directory: 'amixer'
2022-02-25 13:46:40,252 ERROR libqtile core.py:_xpoll():L331 Got an exception in poll loop
Traceback (most recent call last):
  File "/usr/lib/python3.10/site-packages/libqtile/backend/x11/core.py", line 299, in _xpoll
    ret = target(event)
  File "/usr/lib/python3.10/site-packages/libqtile/backend/x11/window.py", line 1119, in handle_ButtonPress
    self.process_button_click(e.event_x, e.event_y, e.detail)
  File "/usr/lib/python3.10/site-packages/libqtile/bar.py", line 462, in process_button_click
    widget.button_press(
  File "/usr/lib/python3.10/site-packages/libqtile/widget/volume.py", line 122, in button_press
    base._TextBox.button_press(self, x, y, button)
  File "/usr/lib/python3.10/site-packages/libqtile/widget/base.py", line 264, in button_press
    cmd()
  File "/usr/lib/python3.10/site-packages/libqtile/widget/volume.py", line 212, in cmd_increase_vol
    subprocess.call(
  File "/usr/lib/python3.10/subprocess.py", line 345, in call
    with Popen(*popenargs, **kwargs) as p:
  File "/usr/lib/python3.10/subprocess.py", line 966, in __init__
    self._execute_child(args, executable, preexec_fn, close_fds,
  File "/usr/lib/python3.10/subprocess.py", line 1842, in _execute_child
    raise child_exception_type(errno_num, err_msg, err_filename)
FileNotFoundError: [Errno 2] No such file or directory: 'amixer'
2022-02-25 13:46:40,269 ERROR libqtile core.py:_xpoll():L331 Got an exception in poll loop
Traceback (most recent call last):
  File "/usr/lib/python3.10/site-packages/libqtile/backend/x11/core.py", line 299, in _xpoll
    ret = target(event)
  File "/usr/lib/python3.10/site-packages/libqtile/backend/x11/window.py", line 1119, in handle_ButtonPress
    self.process_button_click(e.event_x, e.event_y, e.detail)
  File "/usr/lib/python3.10/site-packages/libqtile/bar.py", line 462, in process_button_click
    widget.button_press(
  File "/usr/lib/python3.10/site-packages/libqtile/widget/volume.py", line 122, in button_press
    base._TextBox.button_press(self, x, y, button)
  File "/usr/lib/python3.10/site-packages/libqtile/widget/base.py", line 264, in button_press
    cmd()
  File "/usr/lib/python3.10/site-packages/libqtile/widget/volume.py", line 212, in cmd_increase_vol
    subprocess.call(
  File "/usr/lib/python3.10/subprocess.py", line 345, in call
    with Popen(*popenargs, **kwargs) as p:
  File "/usr/lib/python3.10/subprocess.py", line 966, in __init__
    self._execute_child(args, executable, preexec_fn, close_fds,
  File "/usr/lib/python3.10/subprocess.py", line 1842, in _execute_child
    raise child_exception_type(errno_num, err_msg, err_filename)
FileNotFoundError: [Errno 2] No such file or directory: 'amixer'
2022-02-25 13:46:40,292 ERROR libqtile core.py:_xpoll():L331 Got an exception in poll loop
Traceback (most recent call last):
  File "/usr/lib/python3.10/site-packages/libqtile/backend/x11/core.py", line 299, in _xpoll
    ret = target(event)
  File "/usr/lib/python3.10/site-packages/libqtile/backend/x11/window.py", line 1119, in handle_ButtonPress
    self.process_button_click(e.event_x, e.event_y, e.detail)
  File "/usr/lib/python3.10/site-packages/libqtile/bar.py", line 462, in process_button_click
    widget.button_press(
  File "/usr/lib/python3.10/site-packages/libqtile/widget/volume.py", line 122, in button_press
    base._TextBox.button_press(self, x, y, button)
  File "/usr/lib/python3.10/site-packages/libqtile/widget/base.py", line 264, in button_press
    cmd()
  File "/usr/lib/python3.10/site-packages/libqtile/widget/volume.py", line 212, in cmd_increase_vol
    subprocess.call(
  File "/usr/lib/python3.10/subprocess.py", line 345, in call
    with Popen(*popenargs, **kwargs) as p:
  File "/usr/lib/python3.10/subprocess.py", line 966, in __init__
    self._execute_child(args, executable, preexec_fn, close_fds,
  File "/usr/lib/python3.10/subprocess.py", line 1842, in _execute_child
    raise child_exception_type(errno_num, err_msg, err_filename)
FileNotFoundError: [Errno 2] No such file or directory: 'amixer'
2022-02-25 13:46:40,331 ERROR libqtile core.py:_xpoll():L331 Got an exception in poll loop
Traceback (most recent call last):
  File "/usr/lib/python3.10/site-packages/libqtile/backend/x11/core.py", line 299, in _xpoll
    ret = target(event)
  File "/usr/lib/python3.10/site-packages/libqtile/backend/x11/window.py", line 1119, in handle_ButtonPress
    self.process_button_click(e.event_x, e.event_y, e.detail)
  File "/usr/lib/python3.10/site-packages/libqtile/bar.py", line 462, in process_button_click
    widget.button_press(
  File "/usr/lib/python3.10/site-packages/libqtile/widget/volume.py", line 122, in button_press
    base._TextBox.button_press(self, x, y, button)
  File "/usr/lib/python3.10/site-packages/libqtile/widget/base.py", line 264, in button_press
    cmd()
  File "/usr/lib/python3.10/site-packages/libqtile/widget/volume.py", line 212, in cmd_increase_vol
    subprocess.call(
  File "/usr/lib/python3.10/subprocess.py", line 345, in call
    with Popen(*popenargs, **kwargs) as p:
  File "/usr/lib/python3.10/subprocess.py", line 966, in __init__
    self._execute_child(args, executable, preexec_fn, close_fds,
  File "/usr/lib/python3.10/subprocess.py", line 1842, in _execute_child
    raise child_exception_type(errno_num, err_msg, err_filename)
FileNotFoundError: [Errno 2] No such file or directory: 'amixer'
2022-02-25 13:46:40,389 ERROR libqtile core.py:_xpoll():L331 Got an exception in poll loop
Traceback (most recent call last):
  File "/usr/lib/python3.10/site-packages/libqtile/backend/x11/core.py", line 299, in _xpoll
    ret = target(event)
  File "/usr/lib/python3.10/site-packages/libqtile/backend/x11/window.py", line 1119, in handle_ButtonPress
    self.process_button_click(e.event_x, e.event_y, e.detail)
  File "/usr/lib/python3.10/site-packages/libqtile/bar.py", line 462, in process_button_click
    widget.button_press(
  File "/usr/lib/python3.10/site-packages/libqtile/widget/volume.py", line 122, in button_press
    base._TextBox.button_press(self, x, y, button)
  File "/usr/lib/python3.10/site-packages/libqtile/widget/base.py", line 264, in button_press
    cmd()
  File "/usr/lib/python3.10/site-packages/libqtile/widget/volume.py", line 220, in cmd_decrease_vol
    subprocess.call(
  File "/usr/lib/python3.10/subprocess.py", line 345, in call
    with Popen(*popenargs, **kwargs) as p:
  File "/usr/lib/python3.10/subprocess.py", line 966, in __init__
    self._execute_child(args, executable, preexec_fn, close_fds,
  File "/usr/lib/python3.10/subprocess.py", line 1842, in _execute_child
    raise child_exception_type(errno_num, err_msg, err_filename)
FileNotFoundError: [Errno 2] No such file or directory: 'amixer'
2022-02-25 13:46:40,406 ERROR libqtile core.py:_xpoll():L331 Got an exception in poll loop
Traceback (most recent call last):
  File "/usr/lib/python3.10/site-packages/libqtile/backend/x11/core.py", line 299, in _xpoll
    ret = target(event)
  File "/usr/lib/python3.10/site-packages/libqtile/backend/x11/window.py", line 1119, in handle_ButtonPress
    self.process_button_click(e.event_x, e.event_y, e.detail)
  File "/usr/lib/python3.10/site-packages/libqtile/bar.py", line 462, in process_button_click
    widget.button_press(
  File "/usr/lib/python3.10/site-packages/libqtile/widget/volume.py", line 122, in button_press
    base._TextBox.button_press(self, x, y, button)
  File "/usr/lib/python3.10/site-packages/libqtile/widget/base.py", line 264, in button_press
    cmd()
  File "/usr/lib/python3.10/site-packages/libqtile/widget/volume.py", line 220, in cmd_decrease_vol
    subprocess.call(
  File "/usr/lib/python3.10/subprocess.py", line 345, in call
    with Popen(*popenargs, **kwargs) as p:
  File "/usr/lib/python3.10/subprocess.py", line 966, in __init__
    self._execute_child(args, executable, preexec_fn, close_fds,
  File "/usr/lib/python3.10/subprocess.py", line 1842, in _execute_child
    raise child_exception_type(errno_num, err_msg, err_filename)
FileNotFoundError: [Errno 2] No such file or directory: 'amixer'
2022-02-25 13:46:40,420 ERROR libqtile core.py:_xpoll():L331 Got an exception in poll loop
Traceback (most recent call last):
  File "/usr/lib/python3.10/site-packages/libqtile/backend/x11/core.py", line 299, in _xpoll
    ret = target(event)
  File "/usr/lib/python3.10/site-packages/libqtile/backend/x11/window.py", line 1119, in handle_ButtonPress
    self.process_button_click(e.event_x, e.event_y, e.detail)
  File "/usr/lib/python3.10/site-packages/libqtile/bar.py", line 462, in process_button_click
    widget.button_press(
  File "/usr/lib/python3.10/site-packages/libqtile/widget/volume.py", line 122, in button_press
    base._TextBox.button_press(self, x, y, button)
  File "/usr/lib/python3.10/site-packages/libqtile/widget/base.py", line 264, in button_press
    cmd()
  File "/usr/lib/python3.10/site-packages/libqtile/widget/volume.py", line 220, in cmd_decrease_vol
    subprocess.call(
  File "/usr/lib/python3.10/subprocess.py", line 345, in call
    with Popen(*popenargs, **kwargs) as p:
  File "/usr/lib/python3.10/subprocess.py", line 966, in __init__
    self._execute_child(args, executable, preexec_fn, close_fds,
  File "/usr/lib/python3.10/subprocess.py", line 1842, in _execute_child
    raise child_exception_type(errno_num, err_msg, err_filename)
FileNotFoundError: [Errno 2] No such file or directory: 'amixer'
2022-02-25 13:46:40,434 ERROR libqtile core.py:_xpoll():L331 Got an exception in poll loop
Traceback (most recent call last):
  File "/usr/lib/python3.10/site-packages/libqtile/backend/x11/core.py", line 299, in _xpoll
    ret = target(event)
  File "/usr/lib/python3.10/site-packages/libqtile/backend/x11/window.py", line 1119, in handle_ButtonPress
    self.process_button_click(e.event_x, e.event_y, e.detail)
  File "/usr/lib/python3.10/site-packages/libqtile/bar.py", line 462, in process_button_click
    widget.button_press(
  File "/usr/lib/python3.10/site-packages/libqtile/widget/volume.py", line 122, in button_press
    base._TextBox.button_press(self, x, y, button)
  File "/usr/lib/python3.10/site-packages/libqtile/widget/base.py", line 264, in button_press
    cmd()
  File "/usr/lib/python3.10/site-packages/libqtile/widget/volume.py", line 220, in cmd_decrease_vol
    subprocess.call(
  File "/usr/lib/python3.10/subprocess.py", line 345, in call
    with Popen(*popenargs, **kwargs) as p:
  File "/usr/lib/python3.10/subprocess.py", line 966, in __init__
    self._execute_child(args, executable, preexec_fn, close_fds,
  File "/usr/lib/python3.10/subprocess.py", line 1842, in _execute_child
    raise child_exception_type(errno_num, err_msg, err_filename)
FileNotFoundError: [Errno 2] No such file or directory: 'amixer'
2022-02-25 13:46:40,525 ERROR libqtile core.py:_xpoll():L331 Got an exception in poll loop
Traceback (most recent call last):
  File "/usr/lib/python3.10/site-packages/libqtile/backend/x11/core.py", line 299, in _xpoll
    ret = target(event)
  File "/usr/lib/python3.10/site-packages/libqtile/backend/x11/window.py", line 1119, in handle_ButtonPress
    self.process_button_click(e.event_x, e.event_y, e.detail)
  File "/usr/lib/python3.10/site-packages/libqtile/bar.py", line 462, in process_button_click
    widget.button_press(
  File "/usr/lib/python3.10/site-packages/libqtile/widget/volume.py", line 122, in button_press
    base._TextBox.button_press(self, x, y, button)
  File "/usr/lib/python3.10/site-packages/libqtile/widget/base.py", line 264, in button_press
    cmd()
  File "/usr/lib/python3.10/site-packages/libqtile/widget/volume.py", line 212, in cmd_increase_vol
    subprocess.call(
  File "/usr/lib/python3.10/subprocess.py", line 345, in call
    with Popen(*popenargs, **kwargs) as p:
  File "/usr/lib/python3.10/subprocess.py", line 966, in __init__
    self._execute_child(args, executable, preexec_fn, close_fds,
  File "/usr/lib/python3.10/subprocess.py", line 1842, in _execute_child
    raise child_exception_type(errno_num, err_msg, err_filename)
FileNotFoundError: [Errno 2] No such file or directory: 'amixer'
2022-02-25 13:46:40,545 ERROR libqtile core.py:_xpoll():L331 Got an exception in poll loop
Traceback (most recent call last):
  File "/usr/lib/python3.10/site-packages/libqtile/backend/x11/core.py", line 299, in _xpoll
    ret = target(event)
  File "/usr/lib/python3.10/site-packages/libqtile/backend/x11/window.py", line 1119, in handle_ButtonPress
    self.process_button_click(e.event_x, e.event_y, e.detail)
  File "/usr/lib/python3.10/site-packages/libqtile/bar.py", line 462, in process_button_click
    widget.button_press(
  File "/usr/lib/python3.10/site-packages/libqtile/widget/volume.py", line 122, in button_press
    base._TextBox.button_press(self, x, y, button)
  File "/usr/lib/python3.10/site-packages/libqtile/widget/base.py", line 264, in button_press
    cmd()
  File "/usr/lib/python3.10/site-packages/libqtile/widget/volume.py", line 212, in cmd_increase_vol
    subprocess.call(
  File "/usr/lib/python3.10/subprocess.py", line 345, in call
    with Popen(*popenargs, **kwargs) as p:
  File "/usr/lib/python3.10/subprocess.py", line 966, in __init__
    self._execute_child(args, executable, preexec_fn, close_fds,
  File "/usr/lib/python3.10/subprocess.py", line 1842, in _execute_child
    raise child_exception_type(errno_num, err_msg, err_filename)
FileNotFoundError: [Errno 2] No such file or directory: 'amixer'
2022-02-25 13:46:40,584 ERROR libqtile core.py:_xpoll():L331 Got an exception in poll loop
Traceback (most recent call last):
  File "/usr/lib/python3.10/site-packages/libqtile/backend/x11/core.py", line 299, in _xpoll
    ret = target(event)
  File "/usr/lib/python3.10/site-packages/libqtile/backend/x11/window.py", line 1119, in handle_ButtonPress
    self.process_button_click(e.event_x, e.event_y, e.detail)
  File "/usr/lib/python3.10/site-packages/libqtile/bar.py", line 462, in process_button_click
    widget.button_press(
  File "/usr/lib/python3.10/site-packages/libqtile/widget/volume.py", line 122, in button_press
    base._TextBox.button_press(self, x, y, button)
  File "/usr/lib/python3.10/site-packages/libqtile/widget/base.py", line 264, in button_press
    cmd()
  File "/usr/lib/python3.10/site-packages/libqtile/widget/volume.py", line 212, in cmd_increase_vol
    subprocess.call(
  File "/usr/lib/python3.10/subprocess.py", line 345, in call
    with Popen(*popenargs, **kwargs) as p:
  File "/usr/lib/python3.10/subprocess.py", line 966, in __init__
    self._execute_child(args, executable, preexec_fn, close_fds,
  File "/usr/lib/python3.10/subprocess.py", line 1842, in _execute_child
    raise child_exception_type(errno_num, err_msg, err_filename)
FileNotFoundError: [Errno 2] No such file or directory: 'amixer'
2022-02-25 13:46:40,640 ERROR libqtile core.py:_xpoll():L331 Got an exception in poll loop
Traceback (most recent call last):
  File "/usr/lib/python3.10/site-packages/libqtile/backend/x11/core.py", line 299, in _xpoll
    ret = target(event)
  File "/usr/lib/python3.10/site-packages/libqtile/backend/x11/window.py", line 1119, in handle_ButtonPress
    self.process_button_click(e.event_x, e.event_y, e.detail)
  File "/usr/lib/python3.10/site-packages/libqtile/bar.py", line 462, in process_button_click
    widget.button_press(
  File "/usr/lib/python3.10/site-packages/libqtile/widget/volume.py", line 122, in button_press
    base._TextBox.button_press(self, x, y, button)
  File "/usr/lib/python3.10/site-packages/libqtile/widget/base.py", line 264, in button_press
    cmd()
  File "/usr/lib/python3.10/site-packages/libqtile/widget/volume.py", line 220, in cmd_decrease_vol
    subprocess.call(
  File "/usr/lib/python3.10/subprocess.py", line 345, in call
    with Popen(*popenargs, **kwargs) as p:
  File "/usr/lib/python3.10/subprocess.py", line 966, in __init__
    self._execute_child(args, executable, preexec_fn, close_fds,
  File "/usr/lib/python3.10/subprocess.py", line 1842, in _execute_child
    raise child_exception_type(errno_num, err_msg, err_filename)
FileNotFoundError: [Errno 2] No such file or directory: 'amixer'
2022-02-25 13:46:40,662 ERROR libqtile core.py:_xpoll():L331 Got an exception in poll loop
Traceback (most recent call last):
  File "/usr/lib/python3.10/site-packages/libqtile/backend/x11/core.py", line 299, in _xpoll
    ret = target(event)
  File "/usr/lib/python3.10/site-packages/libqtile/backend/x11/window.py", line 1119, in handle_ButtonPress
    self.process_button_click(e.event_x, e.event_y, e.detail)
  File "/usr/lib/python3.10/site-packages/libqtile/bar.py", line 462, in process_button_click
    widget.button_press(
  File "/usr/lib/python3.10/site-packages/libqtile/widget/volume.py", line 122, in button_press
    base._TextBox.button_press(self, x, y, button)
  File "/usr/lib/python3.10/site-packages/libqtile/widget/base.py", line 264, in button_press
    cmd()
  File "/usr/lib/python3.10/site-packages/libqtile/widget/volume.py", line 220, in cmd_decrease_vol
    subprocess.call(
  File "/usr/lib/python3.10/subprocess.py", line 345, in call
    with Popen(*popenargs, **kwargs) as p:
  File "/usr/lib/python3.10/subprocess.py", line 966, in __init__
    self._execute_child(args, executable, preexec_fn, close_fds,
  File "/usr/lib/python3.10/subprocess.py", line 1842, in _execute_child
    raise child_exception_type(errno_num, err_msg, err_filename)
FileNotFoundError: [Errno 2] No such file or directory: 'amixer'
2022-02-25 13:46:40,679 ERROR libqtile core.py:_xpoll():L331 Got an exception in poll loop
Traceback (most recent call last):
  File "/usr/lib/python3.10/site-packages/libqtile/backend/x11/core.py", line 299, in _xpoll
    ret = target(event)
  File "/usr/lib/python3.10/site-packages/libqtile/backend/x11/window.py", line 1119, in handle_ButtonPress
    self.process_button_click(e.event_x, e.event_y, e.detail)
  File "/usr/lib/python3.10/site-packages/libqtile/bar.py", line 462, in process_button_click
    widget.button_press(
  File "/usr/lib/python3.10/site-packages/libqtile/widget/volume.py", line 122, in button_press
    base._TextBox.button_press(self, x, y, button)
  File "/usr/lib/python3.10/site-packages/libqtile/widget/base.py", line 264, in button_press
    cmd()
  File "/usr/lib/python3.10/site-packages/libqtile/widget/volume.py", line 220, in cmd_decrease_vol
    subprocess.call(
  File "/usr/lib/python3.10/subprocess.py", line 345, in call
    with Popen(*popenargs, **kwargs) as p:
  File "/usr/lib/python3.10/subprocess.py", line 966, in __init__
    self._execute_child(args, executable, preexec_fn, close_fds,
  File "/usr/lib/python3.10/subprocess.py", line 1842, in _execute_child
    raise child_exception_type(errno_num, err_msg, err_filename)
FileNotFoundError: [Errno 2] No such file or directory: 'amixer'
2022-02-25 13:46:40,762 ERROR libqtile core.py:_xpoll():L331 Got an exception in poll loop
Traceback (most recent call last):
  File "/usr/lib/python3.10/site-packages/libqtile/backend/x11/core.py", line 299, in _xpoll
    ret = target(event)
  File "/usr/lib/python3.10/site-packages/libqtile/backend/x11/window.py", line 1119, in handle_ButtonPress
    self.process_button_click(e.event_x, e.event_y, e.detail)
  File "/usr/lib/python3.10/site-packages/libqtile/bar.py", line 462, in process_button_click
    widget.button_press(
  File "/usr/lib/python3.10/site-packages/libqtile/widget/volume.py", line 122, in button_press
    base._TextBox.button_press(self, x, y, button)
  File "/usr/lib/python3.10/site-packages/libqtile/widget/base.py", line 264, in button_press
    cmd()
  File "/usr/lib/python3.10/site-packages/libqtile/widget/volume.py", line 212, in cmd_increase_vol
    subprocess.call(
  File "/usr/lib/python3.10/subprocess.py", line 345, in call
    with Popen(*popenargs, **kwargs) as p:
  File "/usr/lib/python3.10/subprocess.py", line 966, in __init__
    self._execute_child(args, executable, preexec_fn, close_fds,
  File "/usr/lib/python3.10/subprocess.py", line 1842, in _execute_child
    raise child_exception_type(errno_num, err_msg, err_filename)
FileNotFoundError: [Errno 2] No such file or directory: 'amixer'
2022-02-25 13:46:40,779 ERROR libqtile core.py:_xpoll():L331 Got an exception in poll loop
Traceback (most recent call last):
  File "/usr/lib/python3.10/site-packages/libqtile/backend/x11/core.py", line 299, in _xpoll
    ret = target(event)
  File "/usr/lib/python3.10/site-packages/libqtile/backend/x11/window.py", line 1119, in handle_ButtonPress
    self.process_button_click(e.event_x, e.event_y, e.detail)
  File "/usr/lib/python3.10/site-packages/libqtile/bar.py", line 462, in process_button_click
    widget.button_press(
  File "/usr/lib/python3.10/site-packages/libqtile/widget/volume.py", line 122, in button_press
    base._TextBox.button_press(self, x, y, button)
  File "/usr/lib/python3.10/site-packages/libqtile/widget/base.py", line 264, in button_press
    cmd()
  File "/usr/lib/python3.10/site-packages/libqtile/widget/volume.py", line 212, in cmd_increase_vol
    subprocess.call(
  File "/usr/lib/python3.10/subprocess.py", line 345, in call
    with Popen(*popenargs, **kwargs) as p:
  File "/usr/lib/python3.10/subprocess.py", line 966, in __init__
    self._execute_child(args, executable, preexec_fn, close_fds,
  File "/usr/lib/python3.10/subprocess.py", line 1842, in _execute_child
    raise child_exception_type(errno_num, err_msg, err_filename)
FileNotFoundError: [Errno 2] No such file or directory: 'amixer'
2022-02-25 13:46:40,808 ERROR libqtile core.py:_xpoll():L331 Got an exception in poll loop
Traceback (most recent call last):
  File "/usr/lib/python3.10/site-packages/libqtile/backend/x11/core.py", line 299, in _xpoll
    ret = target(event)
  File "/usr/lib/python3.10/site-packages/libqtile/backend/x11/window.py", line 1119, in handle_ButtonPress
    self.process_button_click(e.event_x, e.event_y, e.detail)
  File "/usr/lib/python3.10/site-packages/libqtile/bar.py", line 462, in process_button_click
    widget.button_press(
  File "/usr/lib/python3.10/site-packages/libqtile/widget/volume.py", line 122, in button_press
    base._TextBox.button_press(self, x, y, button)
  File "/usr/lib/python3.10/site-packages/libqtile/widget/base.py", line 264, in button_press
    cmd()
  File "/usr/lib/python3.10/site-packages/libqtile/widget/volume.py", line 212, in cmd_increase_vol
    subprocess.call(
  File "/usr/lib/python3.10/subprocess.py", line 345, in call
    with Popen(*popenargs, **kwargs) as p:
  File "/usr/lib/python3.10/subprocess.py", line 966, in __init__
    self._execute_child(args, executable, preexec_fn, close_fds,
  File "/usr/lib/python3.10/subprocess.py", line 1842, in _execute_child
    raise child_exception_type(errno_num, err_msg, err_filename)
FileNotFoundError: [Errno 2] No such file or directory: 'amixer'
2022-02-25 13:46:40,857 ERROR libqtile core.py:_xpoll():L331 Got an exception in poll loop
Traceback (most recent call last):
  File "/usr/lib/python3.10/site-packages/libqtile/backend/x11/core.py", line 299, in _xpoll
    ret = target(event)
  File "/usr/lib/python3.10/site-packages/libqtile/backend/x11/window.py", line 1119, in handle_ButtonPress
    self.process_button_click(e.event_x, e.event_y, e.detail)
  File "/usr/lib/python3.10/site-packages/libqtile/bar.py", line 462, in process_button_click
    widget.button_press(
  File "/usr/lib/python3.10/site-packages/libqtile/widget/volume.py", line 122, in button_press
    base._TextBox.button_press(self, x, y, button)
  File "/usr/lib/python3.10/site-packages/libqtile/widget/base.py", line 264, in button_press
    cmd()
  File "/usr/lib/python3.10/site-packages/libqtile/widget/volume.py", line 212, in cmd_increase_vol
    subprocess.call(
  File "/usr/lib/python3.10/subprocess.py", line 345, in call
    with Popen(*popenargs, **kwargs) as p:
  File "/usr/lib/python3.10/subprocess.py", line 966, in __init__
    self._execute_child(args, executable, preexec_fn, close_fds,
  File "/usr/lib/python3.10/subprocess.py", line 1842, in _execute_child
    raise child_exception_type(errno_num, err_msg, err_filename)
FileNotFoundError: [Errno 2] No such file or directory: 'amixer'
2022-02-25 13:46:40,949 ERROR libqtile core.py:_xpoll():L331 Got an exception in poll loop
Traceback (most recent call last):
  File "/usr/lib/python3.10/site-packages/libqtile/backend/x11/core.py", line 299, in _xpoll
    ret = target(event)
  File "/usr/lib/python3.10/site-packages/libqtile/backend/x11/window.py", line 1119, in handle_ButtonPress
    self.process_button_click(e.event_x, e.event_y, e.detail)
  File "/usr/lib/python3.10/site-packages/libqtile/bar.py", line 462, in process_button_click
    widget.button_press(
  File "/usr/lib/python3.10/site-packages/libqtile/widget/volume.py", line 122, in button_press
    base._TextBox.button_press(self, x, y, button)
  File "/usr/lib/python3.10/site-packages/libqtile/widget/base.py", line 264, in button_press
    cmd()
  File "/usr/lib/python3.10/site-packages/libqtile/widget/volume.py", line 220, in cmd_decrease_vol
    subprocess.call(
  File "/usr/lib/python3.10/subprocess.py", line 345, in call
    with Popen(*popenargs, **kwargs) as p:
  File "/usr/lib/python3.10/subprocess.py", line 966, in __init__
    self._execute_child(args, executable, preexec_fn, close_fds,
  File "/usr/lib/python3.10/subprocess.py", line 1842, in _execute_child
    raise child_exception_type(errno_num, err_msg, err_filename)
FileNotFoundError: [Errno 2] No such file or directory: 'amixer'
2022-02-25 13:46:41,092 ERROR libqtile core.py:_xpoll():L331 Got an exception in poll loop
Traceback (most recent call last):
  File "/usr/lib/python3.10/site-packages/libqtile/backend/x11/core.py", line 299, in _xpoll
    ret = target(event)
  File "/usr/lib/python3.10/site-packages/libqtile/backend/x11/window.py", line 1119, in handle_ButtonPress
    self.process_button_click(e.event_x, e.event_y, e.detail)
  File "/usr/lib/python3.10/site-packages/libqtile/bar.py", line 462, in process_button_click
    widget.button_press(
  File "/usr/lib/python3.10/site-packages/libqtile/widget/volume.py", line 122, in button_press
    base._TextBox.button_press(self, x, y, button)
  File "/usr/lib/python3.10/site-packages/libqtile/widget/base.py", line 264, in button_press
    cmd()
  File "/usr/lib/python3.10/site-packages/libqtile/widget/volume.py", line 212, in cmd_increase_vol
    subprocess.call(
  File "/usr/lib/python3.10/subprocess.py", line 345, in call
    with Popen(*popenargs, **kwargs) as p:
  File "/usr/lib/python3.10/subprocess.py", line 966, in __init__
    self._execute_child(args, executable, preexec_fn, close_fds,
  File "/usr/lib/python3.10/subprocess.py", line 1842, in _execute_child
    raise child_exception_type(errno_num, err_msg, err_filename)
FileNotFoundError: [Errno 2] No such file or directory: 'amixer'
2022-02-25 13:46:41,175 ERROR libqtile core.py:_xpoll():L331 Got an exception in poll loop
Traceback (most recent call last):
  File "/usr/lib/python3.10/site-packages/libqtile/backend/x11/core.py", line 299, in _xpoll
    ret = target(event)
  File "/usr/lib/python3.10/site-packages/libqtile/backend/x11/window.py", line 1119, in handle_ButtonPress
    self.process_button_click(e.event_x, e.event_y, e.detail)
  File "/usr/lib/python3.10/site-packages/libqtile/bar.py", line 462, in process_button_click
    widget.button_press(
  File "/usr/lib/python3.10/site-packages/libqtile/widget/volume.py", line 122, in button_press
    base._TextBox.button_press(self, x, y, button)
  File "/usr/lib/python3.10/site-packages/libqtile/widget/base.py", line 264, in button_press
    cmd()
  File "/usr/lib/python3.10/site-packages/libqtile/widget/volume.py", line 220, in cmd_decrease_vol
    subprocess.call(
  File "/usr/lib/python3.10/subprocess.py", line 345, in call
    with Popen(*popenargs, **kwargs) as p:
  File "/usr/lib/python3.10/subprocess.py", line 966, in __init__
    self._execute_child(args, executable, preexec_fn, close_fds,
  File "/usr/lib/python3.10/subprocess.py", line 1842, in _execute_child
    raise child_exception_type(errno_num, err_msg, err_filename)
FileNotFoundError: [Errno 2] No such file or directory: 'amixer'
2022-02-25 13:46:41,202 ERROR libqtile core.py:_xpoll():L331 Got an exception in poll loop
Traceback (most recent call last):
  File "/usr/lib/python3.10/site-packages/libqtile/backend/x11/core.py", line 299, in _xpoll
    ret = target(event)
  File "/usr/lib/python3.10/site-packages/libqtile/backend/x11/window.py", line 1119, in handle_ButtonPress
    self.process_button_click(e.event_x, e.event_y, e.detail)
  File "/usr/lib/python3.10/site-packages/libqtile/bar.py", line 462, in process_button_click
    widget.button_press(
  File "/usr/lib/python3.10/site-packages/libqtile/widget/volume.py", line 122, in button_press
    base._TextBox.button_press(self, x, y, button)
  File "/usr/lib/python3.10/site-packages/libqtile/widget/base.py", line 264, in button_press
    cmd()
  File "/usr/lib/python3.10/site-packages/libqtile/widget/volume.py", line 220, in cmd_decrease_vol
    subprocess.call(
  File "/usr/lib/python3.10/subprocess.py", line 345, in call
    with Popen(*popenargs, **kwargs) as p:
  File "/usr/lib/python3.10/subprocess.py", line 966, in __init__
    self._execute_child(args, executable, preexec_fn, close_fds,
  File "/usr/lib/python3.10/subprocess.py", line 1842, in _execute_child
    raise child_exception_type(errno_num, err_msg, err_filename)
FileNotFoundError: [Errno 2] No such file or directory: 'amixer'
2022-02-25 13:46:41,227 ERROR libqtile core.py:_xpoll():L331 Got an exception in poll loop
Traceback (most recent call last):
  File "/usr/lib/python3.10/site-packages/libqtile/backend/x11/core.py", line 299, in _xpoll
    ret = target(event)
  File "/usr/lib/python3.10/site-packages/libqtile/backend/x11/window.py", line 1119, in handle_ButtonPress
    self.process_button_click(e.event_x, e.event_y, e.detail)
  File "/usr/lib/python3.10/site-packages/libqtile/bar.py", line 462, in process_button_click
    widget.button_press(
  File "/usr/lib/python3.10/site-packages/libqtile/widget/volume.py", line 122, in button_press
    base._TextBox.button_press(self, x, y, button)
  File "/usr/lib/python3.10/site-packages/libqtile/widget/base.py", line 264, in button_press
    cmd()
  File "/usr/lib/python3.10/site-packages/libqtile/widget/volume.py", line 220, in cmd_decrease_vol
    subprocess.call(
  File "/usr/lib/python3.10/subprocess.py", line 345, in call
    with Popen(*popenargs, **kwargs) as p:
  File "/usr/lib/python3.10/subprocess.py", line 966, in __init__
    self._execute_child(args, executable, preexec_fn, close_fds,
  File "/usr/lib/python3.10/subprocess.py", line 1842, in _execute_child
    raise child_exception_type(errno_num, err_msg, err_filename)
FileNotFoundError: [Errno 2] No such file or directory: 'amixer'
2022-02-25 13:46:41,262 ERROR libqtile core.py:_xpoll():L331 Got an exception in poll loop
Traceback (most recent call last):
  File "/usr/lib/python3.10/site-packages/libqtile/backend/x11/core.py", line 299, in _xpoll
    ret = target(event)
  File "/usr/lib/python3.10/site-packages/libqtile/backend/x11/window.py", line 1119, in handle_ButtonPress
    self.process_button_click(e.event_x, e.event_y, e.detail)
  File "/usr/lib/python3.10/site-packages/libqtile/bar.py", line 462, in process_button_click
    widget.button_press(
  File "/usr/lib/python3.10/site-packages/libqtile/widget/volume.py", line 122, in button_press
    base._TextBox.button_press(self, x, y, button)
  File "/usr/lib/python3.10/site-packages/libqtile/widget/base.py", line 264, in button_press
    cmd()
  File "/usr/lib/python3.10/site-packages/libqtile/widget/volume.py", line 220, in cmd_decrease_vol
    subprocess.call(
  File "/usr/lib/python3.10/subprocess.py", line 345, in call
    with Popen(*popenargs, **kwargs) as p:
  File "/usr/lib/python3.10/subprocess.py", line 966, in __init__
    self._execute_child(args, executable, preexec_fn, close_fds,
  File "/usr/lib/python3.10/subprocess.py", line 1842, in _execute_child
    raise child_exception_type(errno_num, err_msg, err_filename)
FileNotFoundError: [Errno 2] No such file or directory: 'amixer'
2022-02-25 13:46:41,305 ERROR libqtile core.py:_xpoll():L331 Got an exception in poll loop
Traceback (most recent call last):
  File "/usr/lib/python3.10/site-packages/libqtile/backend/x11/core.py", line 299, in _xpoll
    ret = target(event)
  File "/usr/lib/python3.10/site-packages/libqtile/backend/x11/window.py", line 1119, in handle_ButtonPress
    self.process_button_click(e.event_x, e.event_y, e.detail)
  File "/usr/lib/python3.10/site-packages/libqtile/bar.py", line 462, in process_button_click
    widget.button_press(
  File "/usr/lib/python3.10/site-packages/libqtile/widget/volume.py", line 122, in button_press
    base._TextBox.button_press(self, x, y, button)
  File "/usr/lib/python3.10/site-packages/libqtile/widget/base.py", line 264, in button_press
    cmd()
  File "/usr/lib/python3.10/site-packages/libqtile/widget/volume.py", line 212, in cmd_increase_vol
    subprocess.call(
  File "/usr/lib/python3.10/subprocess.py", line 345, in call
    with Popen(*popenargs, **kwargs) as p:
  File "/usr/lib/python3.10/subprocess.py", line 966, in __init__
    self._execute_child(args, executable, preexec_fn, close_fds,
  File "/usr/lib/python3.10/subprocess.py", line 1842, in _execute_child
    raise child_exception_type(errno_num, err_msg, err_filename)
FileNotFoundError: [Errno 2] No such file or directory: 'amixer'
2022-02-25 13:46:41,579 ERROR libqtile core.py:_xpoll():L331 Got an exception in poll loop
Traceback (most recent call last):
  File "/usr/lib/python3.10/site-packages/libqtile/backend/x11/core.py", line 299, in _xpoll
    ret = target(event)
  File "/usr/lib/python3.10/site-packages/libqtile/backend/x11/window.py", line 1119, in handle_ButtonPress
    self.process_button_click(e.event_x, e.event_y, e.detail)
  File "/usr/lib/python3.10/site-packages/libqtile/bar.py", line 462, in process_button_click
    widget.button_press(
  File "/usr/lib/python3.10/site-packages/libqtile/widget/volume.py", line 122, in button_press
    base._TextBox.button_press(self, x, y, button)
  File "/usr/lib/python3.10/site-packages/libqtile/widget/base.py", line 264, in button_press
    cmd()
  File "/usr/lib/python3.10/site-packages/libqtile/widget/volume.py", line 228, in cmd_mute
    subprocess.call(self.create_amixer_command("-q", "sset", self.channel, "toggle"))
  File "/usr/lib/python3.10/subprocess.py", line 345, in call
    with Popen(*popenargs, **kwargs) as p:
  File "/usr/lib/python3.10/subprocess.py", line 966, in __init__
    self._execute_child(args, executable, preexec_fn, close_fds,
  File "/usr/lib/python3.10/subprocess.py", line 1842, in _execute_child
    raise child_exception_type(errno_num, err_msg, err_filename)
FileNotFoundError: [Errno 2] No such file or directory: 'amixer'
2022-02-25 14:23:04,582 ERROR libqtile core.py:_xpoll():L331 Got an exception in poll loop
Traceback (most recent call last):
  File "/usr/lib/python3.10/site-packages/libqtile/backend/x11/core.py", line 299, in _xpoll
    ret = target(event)
  File "/usr/lib/python3.10/site-packages/libqtile/backend/x11/window.py", line 1137, in handle_KeyPress
    self.process_key_press(keysym)
  File "/usr/lib/python3.10/site-packages/libqtile/bar.py", line 508, in process_key_press
    if self.has_keyboard:
  File "/usr/lib/python3.10/site-packages/libqtile/configurable.py", line 49, in __getattr__
    raise AttributeError("%s has no attribute: %s" % (cname, name))
AttributeError: Bar has no attribute: has_keyboard
2022-02-25 14:23:07,754 ERROR libqtile core.py:_xpoll():L331 Got an exception in poll loop
Traceback (most recent call last):
  File "/usr/lib/python3.10/site-packages/libqtile/backend/x11/core.py", line 299, in _xpoll
    ret = target(event)
  File "/usr/lib/python3.10/site-packages/libqtile/backend/x11/window.py", line 1137, in handle_KeyPress
    self.process_key_press(keysym)
  File "/usr/lib/python3.10/site-packages/libqtile/bar.py", line 508, in process_key_press
    if self.has_keyboard:
  File "/usr/lib/python3.10/site-packages/libqtile/configurable.py", line 49, in __getattr__
    raise AttributeError("%s has no attribute: %s" % (cname, name))
AttributeError: Bar has no attribute: has_keyboard
2022-02-25 16:44:17,618 ERROR libqtile manager.py:process_key_event():L390 KB command error kill: No object window in path 'window'
2022-02-25 16:44:30,290 WARNING libqtile lifecycle.py:_atexit():L38 Qtile will now terminate
2022-02-28 12:18:13,362 ERROR libqtile hook.py:fire():L392 Error in hook startup_once
Traceback (most recent call last):
  File "/usr/lib/python3.10/site-packages/libqtile/hook.py", line 390, in fire
    i(*args, **kwargs)
  File "/home/mk/.config/qtile/config.py", line 258, in start_once
    subprocess.call([home + '/.config/qtile/autostart.sh'])
  File "/usr/lib/python3.10/subprocess.py", line 345, in call
    with Popen(*popenargs, **kwargs) as p:
  File "/usr/lib/python3.10/subprocess.py", line 966, in __init__
    self._execute_child(args, executable, preexec_fn, close_fds,
  File "/usr/lib/python3.10/subprocess.py", line 1842, in _execute_child
    raise child_exception_type(errno_num, err_msg, err_filename)
PermissionError: [Errno 13] Permission denied: '/home/mk/.config/qtile/autostart.sh'
2022-02-28 12:18:51,389 WARNING libqtile lifecycle.py:_atexit():L38 Qtile will now terminate
2022-02-28 12:44:15,349 ERROR libqtile bar.py:_configure_widget():L324 Systray widget crashed during _configure with error: ConfigError('Only one Systray can be used.')
2022-02-28 13:09:35,941 WARNING libqtile lifecycle.py:_atexit():L38 Qtile will now terminate
2022-02-28 14:01:56,714 ERROR libqtile core.py:_xpoll():L331 Got an exception in poll loop
Traceback (most recent call last):
  File "/usr/lib/python3.10/site-packages/libqtile/backend/x11/core.py", line 299, in _xpoll
    ret = target(event)
  File "/usr/lib/python3.10/site-packages/libqtile/backend/x11/window.py", line 1119, in handle_ButtonPress
    self.process_button_click(e.event_x, e.event_y, e.detail)
  File "/usr/lib/python3.10/site-packages/libqtile/bar.py", line 462, in process_button_click
    widget.button_press(
  File "/usr/lib/python3.10/site-packages/libqtile/widget/base.py", line 264, in button_press
    cmd()
  File "/home/mk/.config/qtile/config.py", line 163, in <lambda>
    widget.Image(filename = "~/.config/qtile/arch.png",scale = "Trye", mouse_callbacks = {'Button1': lambda: qtile.cmd_spawn(terminal)}),
NameError: name 'qtile' is not defined
2022-02-28 14:43:21,781 WARNING libqtile lifecycle.py:_atexit():L38 Qtile will now terminate
2022-02-28 14:48:01,832 ERROR libqtile base.py:_wrapper():L345 got exception from widget timer
Traceback (most recent call last):
  File "/usr/lib/python3.10/site-packages/libqtile/widget/base.py", line 343, in _wrapper
    method(*method_args)
  File "/usr/lib/python3.10/site-packages/libqtile/widget/volume.py", line 126, in update
    vol = self.get_volume()
  File "/usr/lib/python3.10/site-packages/libqtile/widget/volume.py", line 188, in get_volume
    mixer_out = self.call_process(get_volume_cmd)
  File "/usr/lib/python3.10/site-packages/libqtile/widget/base.py", line 330, in call_process
    return subprocess.check_output(command, **kwargs, encoding="utf-8")
  File "/usr/lib/python3.10/subprocess.py", line 420, in check_output
    return run(*popenargs, stdout=PIPE, timeout=timeout, check=True,
  File "/usr/lib/python3.10/subprocess.py", line 501, in run
    with Popen(*popenargs, **kwargs) as process:
  File "/usr/lib/python3.10/subprocess.py", line 966, in __init__
    self._execute_child(args, executable, preexec_fn, close_fds,
  File "/usr/lib/python3.10/subprocess.py", line 1842, in _execute_child
    raise child_exception_type(errno_num, err_msg, err_filename)
FileNotFoundError: [Errno 2] No such file or directory: 'amixer'
2022-02-28 14:48:04,174 ERROR libqtile core.py:_xpoll():L331 Got an exception in poll loop
Traceback (most recent call last):
  File "/usr/lib/python3.10/site-packages/libqtile/backend/x11/core.py", line 299, in _xpoll
    ret = target(event)
  File "/usr/lib/python3.10/site-packages/libqtile/backend/x11/window.py", line 1119, in handle_ButtonPress
    self.process_button_click(e.event_x, e.event_y, e.detail)
  File "/usr/lib/python3.10/site-packages/libqtile/bar.py", line 462, in process_button_click
    widget.button_press(
  File "/usr/lib/python3.10/site-packages/libqtile/widget/volume.py", line 122, in button_press
    base._TextBox.button_press(self, x, y, button)
  File "/usr/lib/python3.10/site-packages/libqtile/widget/base.py", line 264, in button_press
    cmd()
  File "/usr/lib/python3.10/site-packages/libqtile/widget/volume.py", line 228, in cmd_mute
    subprocess.call(self.create_amixer_command("-q", "sset", self.channel, "toggle"))
  File "/usr/lib/python3.10/subprocess.py", line 345, in call
    with Popen(*popenargs, **kwargs) as p:
  File "/usr/lib/python3.10/subprocess.py", line 966, in __init__
    self._execute_child(args, executable, preexec_fn, close_fds,
  File "/usr/lib/python3.10/subprocess.py", line 1842, in _execute_child
    raise child_exception_type(errno_num, err_msg, err_filename)
FileNotFoundError: [Errno 2] No such file or directory: 'amixer'
2022-02-28 14:48:21,585 ERROR libqtile base.py:_wrapper():L345 got exception from widget timer
Traceback (most recent call last):
  File "/usr/lib/python3.10/site-packages/libqtile/widget/base.py", line 343, in _wrapper
    method(*method_args)
  File "/usr/lib/python3.10/site-packages/libqtile/widget/volume.py", line 126, in update
    vol = self.get_volume()
  File "/usr/lib/python3.10/site-packages/libqtile/widget/volume.py", line 188, in get_volume
    mixer_out = self.call_process(get_volume_cmd)
  File "/usr/lib/python3.10/site-packages/libqtile/widget/base.py", line 330, in call_process
    return subprocess.check_output(command, **kwargs, encoding="utf-8")
  File "/usr/lib/python3.10/subprocess.py", line 420, in check_output
    return run(*popenargs, stdout=PIPE, timeout=timeout, check=True,
  File "/usr/lib/python3.10/subprocess.py", line 501, in run
    with Popen(*popenargs, **kwargs) as process:
  File "/usr/lib/python3.10/subprocess.py", line 966, in __init__
    self._execute_child(args, executable, preexec_fn, close_fds,
  File "/usr/lib/python3.10/subprocess.py", line 1842, in _execute_child
    raise child_exception_type(errno_num, err_msg, err_filename)
FileNotFoundError: [Errno 2] No such file or directory: 'amixer'
2022-02-28 14:54:48,859 ERROR libqtile core.py:_xpoll():L331 Got an exception in poll loop
Traceback (most recent call last):
  File "/usr/lib/python3.10/site-packages/libqtile/backend/x11/core.py", line 299, in _xpoll
    ret = target(event)
  File "/usr/lib/python3.10/site-packages/libqtile/backend/x11/window.py", line 1119, in handle_ButtonPress
    self.process_button_click(e.event_x, e.event_y, e.detail)
  File "/usr/lib/python3.10/site-packages/libqtile/bar.py", line 462, in process_button_click
    widget.button_press(
  File "/usr/lib/python3.10/site-packages/libqtile/widget/volume.py", line 122, in button_press
    base._TextBox.button_press(self, x, y, button)
  File "/usr/lib/python3.10/site-packages/libqtile/widget/base.py", line 264, in button_press
    cmd()
  File "/usr/lib/python3.10/site-packages/libqtile/widget/volume.py", line 228, in cmd_mute
    subprocess.call(self.create_amixer_command("-q", "sset", self.channel, "toggle"))
  File "/usr/lib/python3.10/subprocess.py", line 345, in call
    with Popen(*popenargs, **kwargs) as p:
  File "/usr/lib/python3.10/subprocess.py", line 966, in __init__
    self._execute_child(args, executable, preexec_fn, close_fds,
  File "/usr/lib/python3.10/subprocess.py", line 1842, in _execute_child
    raise child_exception_type(errno_num, err_msg, err_filename)
FileNotFoundError: [Errno 2] No such file or directory: 'amixer'
2022-02-28 14:58:48,283 ERROR libqtile base.py:_wrapper():L345 got exception from widget timer
Traceback (most recent call last):
  File "/usr/lib/python3.10/site-packages/libqtile/widget/base.py", line 343, in _wrapper
    method(*method_args)
  File "/usr/lib/python3.10/site-packages/libqtile/widget/volume.py", line 126, in update
    vol = self.get_volume()
  File "/usr/lib/python3.10/site-packages/libqtile/widget/volume.py", line 188, in get_volume
    mixer_out = self.call_process(get_volume_cmd)
  File "/usr/lib/python3.10/site-packages/libqtile/widget/base.py", line 330, in call_process
    return subprocess.check_output(command, **kwargs, encoding="utf-8")
  File "/usr/lib/python3.10/subprocess.py", line 420, in check_output
    return run(*popenargs, stdout=PIPE, timeout=timeout, check=True,
  File "/usr/lib/python3.10/subprocess.py", line 501, in run
    with Popen(*popenargs, **kwargs) as process:
  File "/usr/lib/python3.10/subprocess.py", line 966, in __init__
    self._execute_child(args, executable, preexec_fn, close_fds,
  File "/usr/lib/python3.10/subprocess.py", line 1842, in _execute_child
    raise child_exception_type(errno_num, err_msg, err_filename)
FileNotFoundError: [Errno 2] No such file or directory: 'pamixer --get-volume'
2022-02-28 14:58:52,910 ERROR libqtile base.py:_wrapper():L345 got exception from widget timer
Traceback (most recent call last):
  File "/usr/lib/python3.10/site-packages/libqtile/widget/base.py", line 343, in _wrapper
    method(*method_args)
  File "/usr/lib/python3.10/site-packages/libqtile/widget/volume.py", line 126, in update
    vol = self.get_volume()
  File "/usr/lib/python3.10/site-packages/libqtile/widget/volume.py", line 188, in get_volume
    mixer_out = self.call_process(get_volume_cmd)
  File "/usr/lib/python3.10/site-packages/libqtile/widget/base.py", line 330, in call_process
    return subprocess.check_output(command, **kwargs, encoding="utf-8")
  File "/usr/lib/python3.10/subprocess.py", line 420, in check_output
    return run(*popenargs, stdout=PIPE, timeout=timeout, check=True,
  File "/usr/lib/python3.10/subprocess.py", line 501, in run
    with Popen(*popenargs, **kwargs) as process:
  File "/usr/lib/python3.10/subprocess.py", line 966, in __init__
    self._execute_child(args, executable, preexec_fn, close_fds,
  File "/usr/lib/python3.10/subprocess.py", line 1842, in _execute_child
    raise child_exception_type(errno_num, err_msg, err_filename)
FileNotFoundError: [Errno 2] No such file or directory: 'pamixer --get-volume'
2022-02-28 14:59:35,389 ERROR libqtile core.py:_xpoll():L331 Got an exception in poll loop
Traceback (most recent call last):
  File "/usr/lib/python3.10/site-packages/libqtile/backend/x11/core.py", line 299, in _xpoll
    ret = target(event)
  File "/usr/lib/python3.10/site-packages/libqtile/backend/x11/window.py", line 1119, in handle_ButtonPress
    self.process_button_click(e.event_x, e.event_y, e.detail)
  File "/usr/lib/python3.10/site-packages/libqtile/bar.py", line 462, in process_button_click
    widget.button_press(
  File "/usr/lib/python3.10/site-packages/libqtile/widget/volume.py", line 122, in button_press
    base._TextBox.button_press(self, x, y, button)
  File "/usr/lib/python3.10/site-packages/libqtile/widget/base.py", line 264, in button_press
    cmd()
  File "/usr/lib/python3.10/site-packages/libqtile/widget/volume.py", line 228, in cmd_mute
    subprocess.call(self.create_amixer_command("-q", "sset", self.channel, "toggle"))
  File "/usr/lib/python3.10/subprocess.py", line 345, in call
    with Popen(*popenargs, **kwargs) as p:
  File "/usr/lib/python3.10/subprocess.py", line 966, in __init__
    self._execute_child(args, executable, preexec_fn, close_fds,
  File "/usr/lib/python3.10/subprocess.py", line 1842, in _execute_child
    raise child_exception_type(errno_num, err_msg, err_filename)
FileNotFoundError: [Errno 2] No such file or directory: 'amixer'
2022-02-28 16:51:41,764 WARNING libqtile lifecycle.py:_atexit():L38 Qtile will now terminate
2022-02-28 16:55:28,904 WARNING libqtile lifecycle.py:_atexit():L38 Qtile will now terminate
2022-02-28 17:02:00,356 WARNING libqtile lifecycle.py:_atexit():L38 Qtile will now terminate
2022-02-28 17:05:37,791 WARNING libqtile lifecycle.py:_atexit():L34 Restarting Qtile with os.execv(...)
2022-02-28 17:05:38,896 WARNING libqtile lifecycle.py:_atexit():L34 Restarting Qtile with os.execv(...)
2022-02-28 17:05:40,512 WARNING libqtile lifecycle.py:_atexit():L34 Restarting Qtile with os.execv(...)
2022-02-28 17:06:12,252 WARNING libqtile lifecycle.py:_atexit():L34 Restarting Qtile with os.execv(...)
2022-02-28 19:31:16,012 ERROR libqtile hook.py:fire():L392 Error in hook client_name_updated
Traceback (most recent call last):
  File "/usr/lib/python3.10/site-packages/libqtile/hook.py", line 390, in fire
    i(*args, **kwargs)
  File "/usr/lib/python3.10/site-packages/libqtile/widget/windowtabs.py", line 81, in update
    self.text = self.separator.join(names)
  File "/usr/lib/python3.10/site-packages/libqtile/widget/base.py", line 396, in text
    self.layout.text = self.formatted_text
  File "/usr/lib/python3.10/site-packages/libqtile/drawer.py", line 72, in text
    attrlist, value, accel_char = pangocffi.parse_markup(value)
  File "/usr/lib/python3.10/site-packages/libqtile/pangocffi.py", line 186, in parse_markup
    raise Exception("parse_markup() failed for %s" % value)
Exception: parse_markup() failed for b'<b>Error reading Qtile Config Files - Software & Applications - Manjaro Linux Forum - Brave</b> | Im Leaving My Board Sponsor... - YouTube - Brave'
2022-02-28 19:31:16,013 ERROR libqtile hook.py:fire():L392 Error in hook client_name_updated
Traceback (most recent call last):
  File "/usr/lib/python3.10/site-packages/libqtile/hook.py", line 390, in fire
    i(*args, **kwargs)
  File "/usr/lib/python3.10/site-packages/libqtile/widget/windowtabs.py", line 81, in update
    self.text = self.separator.join(names)
  File "/usr/lib/python3.10/site-packages/libqtile/widget/base.py", line 396, in text
    self.layout.text = self.formatted_text
  File "/usr/lib/python3.10/site-packages/libqtile/drawer.py", line 72, in text
    attrlist, value, accel_char = pangocffi.parse_markup(value)
  File "/usr/lib/python3.10/site-packages/libqtile/pangocffi.py", line 186, in parse_markup
    raise Exception("parse_markup() failed for %s" % value)
Exception: parse_markup() failed for b'<b>Error reading Qtile Config Files - Software & Applications - Manjaro Linux Forum - Brave</b> | Im Leaving My Board Sponsor... - YouTube - Brave'
2022-02-28 19:31:17,045 ERROR libqtile hook.py:fire():L392 Error in hook client_name_updated
Traceback (most recent call last):
  File "/usr/lib/python3.10/site-packages/libqtile/hook.py", line 390, in fire
    i(*args, **kwargs)
  File "/usr/lib/python3.10/site-packages/libqtile/widget/windowtabs.py", line 81, in update
    self.text = self.separator.join(names)
  File "/usr/lib/python3.10/site-packages/libqtile/widget/base.py", line 396, in text
    self.layout.text = self.formatted_text
  File "/usr/lib/python3.10/site-packages/libqtile/drawer.py", line 72, in text
    attrlist, value, accel_char = pangocffi.parse_markup(value)
  File "/usr/lib/python3.10/site-packages/libqtile/pangocffi.py", line 186, in parse_markup
    raise Exception("parse_markup() failed for %s" % value)
Exception: parse_markup() failed for b'<b>Error reading Qtile Config Files - Support / Software & Applications - Manjaro Linux Forum - Brave</b> | Im Leaving My Board Sponsor... - YouTube - Brave'
2022-02-28 19:31:17,045 ERROR libqtile hook.py:fire():L392 Error in hook client_name_updated
Traceback (most recent call last):
  File "/usr/lib/python3.10/site-packages/libqtile/hook.py", line 390, in fire
    i(*args, **kwargs)
  File "/usr/lib/python3.10/site-packages/libqtile/widget/windowtabs.py", line 81, in update
    self.text = self.separator.join(names)
  File "/usr/lib/python3.10/site-packages/libqtile/widget/base.py", line 396, in text
    self.layout.text = self.formatted_text
  File "/usr/lib/python3.10/site-packages/libqtile/drawer.py", line 72, in text
    attrlist, value, accel_char = pangocffi.parse_markup(value)
  File "/usr/lib/python3.10/site-packages/libqtile/pangocffi.py", line 186, in parse_markup
    raise Exception("parse_markup() failed for %s" % value)
Exception: parse_markup() failed for b'<b>Error reading Qtile Config Files - Support / Software & Applications - Manjaro Linux Forum - Brave</b> | Im Leaving My Board Sponsor... - YouTube - Brave'
2022-02-28 19:31:30,477 ERROR libqtile hook.py:fire():L392 Error in hook focus_change
Traceback (most recent call last):
  File "/usr/lib/python3.10/site-packages/libqtile/hook.py", line 390, in fire
    i(*args, **kwargs)
  File "/usr/lib/python3.10/site-packages/libqtile/widget/windowtabs.py", line 81, in update
    self.text = self.separator.join(names)
  File "/usr/lib/python3.10/site-packages/libqtile/widget/base.py", line 396, in text
    self.layout.text = self.formatted_text
  File "/usr/lib/python3.10/site-packages/libqtile/drawer.py", line 72, in text
    attrlist, value, accel_char = pangocffi.parse_markup(value)
  File "/usr/lib/python3.10/site-packages/libqtile/pangocffi.py", line 186, in parse_markup
    raise Exception("parse_markup() failed for %s" % value)
Exception: parse_markup() failed for b'Error reading Qtile Config Files - Support / Software & Applications - Manjaro Linux Forum - Brave | <b>Im Leaving My Board Sponsor... - YouTube - Brave</b>'
2022-02-28 19:31:58,665 ERROR libqtile hook.py:fire():L392 Error in hook focus_change
Traceback (most recent call last):
  File "/usr/lib/python3.10/site-packages/libqtile/hook.py", line 390, in fire
    i(*args, **kwargs)
  File "/usr/lib/python3.10/site-packages/libqtile/widget/windowtabs.py", line 81, in update
    self.text = self.separator.join(names)
  File "/usr/lib/python3.10/site-packages/libqtile/widget/base.py", line 396, in text
    self.layout.text = self.formatted_text
  File "/usr/lib/python3.10/site-packages/libqtile/drawer.py", line 72, in text
    attrlist, value, accel_char = pangocffi.parse_markup(value)
  File "/usr/lib/python3.10/site-packages/libqtile/pangocffi.py", line 186, in parse_markup
    raise Exception("parse_markup() failed for %s" % value)
Exception: parse_markup() failed for b'<b>Error reading Qtile Config Files - Support / Software & Applications - Manjaro Linux Forum - Brave</b> | Im Leaving My Board Sponsor... - YouTube - Brave'
2022-02-28 19:31:58,902 ERROR libqtile hook.py:fire():L392 Error in hook focus_change
Traceback (most recent call last):
  File "/usr/lib/python3.10/site-packages/libqtile/hook.py", line 390, in fire
    i(*args, **kwargs)
  File "/usr/lib/python3.10/site-packages/libqtile/widget/windowtabs.py", line 81, in update
    self.text = self.separator.join(names)
  File "/usr/lib/python3.10/site-packages/libqtile/widget/base.py", line 396, in text
    self.layout.text = self.formatted_text
  File "/usr/lib/python3.10/site-packages/libqtile/drawer.py", line 72, in text
    attrlist, value, accel_char = pangocffi.parse_markup(value)
  File "/usr/lib/python3.10/site-packages/libqtile/pangocffi.py", line 186, in parse_markup
    raise Exception("parse_markup() failed for %s" % value)
Exception: parse_markup() failed for b'<b>Error reading Qtile Config Files - Support / Software & Applications - Manjaro Linux Forum - Brave</b> | Im Leaving My Board Sponsor... - YouTube - Brave'
2022-02-28 19:31:58,921 ERROR libqtile hook.py:fire():L392 Error in hook focus_change
Traceback (most recent call last):
  File "/usr/lib/python3.10/site-packages/libqtile/hook.py", line 390, in fire
    i(*args, **kwargs)
  File "/usr/lib/python3.10/site-packages/libqtile/widget/windowtabs.py", line 81, in update
    self.text = self.separator.join(names)
  File "/usr/lib/python3.10/site-packages/libqtile/widget/base.py", line 396, in text
    self.layout.text = self.formatted_text
  File "/usr/lib/python3.10/site-packages/libqtile/drawer.py", line 72, in text
    attrlist, value, accel_char = pangocffi.parse_markup(value)
  File "/usr/lib/python3.10/site-packages/libqtile/pangocffi.py", line 186, in parse_markup
    raise Exception("parse_markup() failed for %s" % value)
Exception: parse_markup() failed for b'<b>Error reading Qtile Config Files - Support / Software & Applications - Manjaro Linux Forum - Brave</b> | Im Leaving My Board Sponsor... - YouTube - Brave'
2022-02-28 19:31:59,240 ERROR libqtile hook.py:fire():L392 Error in hook focus_change
Traceback (most recent call last):
  File "/usr/lib/python3.10/site-packages/libqtile/hook.py", line 390, in fire
    i(*args, **kwargs)
  File "/usr/lib/python3.10/site-packages/libqtile/widget/windowtabs.py", line 81, in update
    self.text = self.separator.join(names)
  File "/usr/lib/python3.10/site-packages/libqtile/widget/base.py", line 396, in text
    self.layout.text = self.formatted_text
  File "/usr/lib/python3.10/site-packages/libqtile/drawer.py", line 72, in text
    attrlist, value, accel_char = pangocffi.parse_markup(value)
  File "/usr/lib/python3.10/site-packages/libqtile/pangocffi.py", line 186, in parse_markup
    raise Exception("parse_markup() failed for %s" % value)
Exception: parse_markup() failed for b'<b>Error reading Qtile Config Files - Support / Software & Applications - Manjaro Linux Forum - Brave</b> | Im Leaving My Board Sponsor... - YouTube - Brave'
2022-02-28 19:31:59,987 ERROR libqtile hook.py:fire():L392 Error in hook focus_change
Traceback (most recent call last):
  File "/usr/lib/python3.10/site-packages/libqtile/hook.py", line 390, in fire
    i(*args, **kwargs)
  File "/usr/lib/python3.10/site-packages/libqtile/widget/windowtabs.py", line 81, in update
    self.text = self.separator.join(names)
  File "/usr/lib/python3.10/site-packages/libqtile/widget/base.py", line 396, in text
    self.layout.text = self.formatted_text
  File "/usr/lib/python3.10/site-packages/libqtile/drawer.py", line 72, in text
    attrlist, value, accel_char = pangocffi.parse_markup(value)
  File "/usr/lib/python3.10/site-packages/libqtile/pangocffi.py", line 186, in parse_markup
    raise Exception("parse_markup() failed for %s" % value)
Exception: parse_markup() failed for b'<b>Error reading Qtile Config Files - Support / Software & Applications - Manjaro Linux Forum - Brave</b> | Im Leaving My Board Sponsor... - YouTube - Brave'
2022-02-28 19:32:09,290 ERROR libqtile hook.py:fire():L392 Error in hook focus_change
Traceback (most recent call last):
  File "/usr/lib/python3.10/site-packages/libqtile/hook.py", line 390, in fire
    i(*args, **kwargs)
  File "/usr/lib/python3.10/site-packages/libqtile/widget/windowtabs.py", line 81, in update
    self.text = self.separator.join(names)
  File "/usr/lib/python3.10/site-packages/libqtile/widget/base.py", line 396, in text
    self.layout.text = self.formatted_text
  File "/usr/lib/python3.10/site-packages/libqtile/drawer.py", line 72, in text
    attrlist, value, accel_char = pangocffi.parse_markup(value)
  File "/usr/lib/python3.10/site-packages/libqtile/pangocffi.py", line 186, in parse_markup
    raise Exception("parse_markup() failed for %s" % value)
Exception: parse_markup() failed for b'<b>Error reading Qtile Config Files - Support / Software & Applications - Manjaro Linux Forum - Brave</b> | Im Leaving My Board Sponsor... - YouTube - Brave'
2022-02-28 19:32:10,913 ERROR libqtile hook.py:fire():L392 Error in hook focus_change
Traceback (most recent call last):
  File "/usr/lib/python3.10/site-packages/libqtile/hook.py", line 390, in fire
    i(*args, **kwargs)
  File "/usr/lib/python3.10/site-packages/libqtile/widget/windowtabs.py", line 81, in update
    self.text = self.separator.join(names)
  File "/usr/lib/python3.10/site-packages/libqtile/widget/base.py", line 396, in text
    self.layout.text = self.formatted_text
  File "/usr/lib/python3.10/site-packages/libqtile/drawer.py", line 72, in text
    attrlist, value, accel_char = pangocffi.parse_markup(value)
  File "/usr/lib/python3.10/site-packages/libqtile/pangocffi.py", line 186, in parse_markup
    raise Exception("parse_markup() failed for %s" % value)
Exception: parse_markup() failed for b'<b>Error reading Qtile Config Files - Support / Software & Applications - Manjaro Linux Forum - Brave</b> | Im Leaving My Board Sponsor... - YouTube - Brave'
2022-02-28 19:32:16,699 ERROR libqtile hook.py:fire():L392 Error in hook focus_change
Traceback (most recent call last):
  File "/usr/lib/python3.10/site-packages/libqtile/hook.py", line 390, in fire
    i(*args, **kwargs)
  File "/usr/lib/python3.10/site-packages/libqtile/widget/windowtabs.py", line 81, in update
    self.text = self.separator.join(names)
  File "/usr/lib/python3.10/site-packages/libqtile/widget/base.py", line 396, in text
    self.layout.text = self.formatted_text
  File "/usr/lib/python3.10/site-packages/libqtile/drawer.py", line 72, in text
    attrlist, value, accel_char = pangocffi.parse_markup(value)
  File "/usr/lib/python3.10/site-packages/libqtile/pangocffi.py", line 186, in parse_markup
    raise Exception("parse_markup() failed for %s" % value)
Exception: parse_markup() failed for b'<b>Error reading Qtile Config Files - Support / Software & Applications - Manjaro Linux Forum - Brave</b> | Im Leaving My Board Sponsor... - YouTube - Brave'
2022-02-28 19:39:04,452 ERROR libqtile manager.py:process_key_event():L390 KB command error right: No such command
2022-02-28 19:39:06,791 ERROR libqtile manager.py:process_key_event():L390 KB command error shuffle_right: No such command
2022-02-28 19:39:06,979 ERROR libqtile manager.py:process_key_event():L390 KB command error shuffle_right: No such command
2022-02-28 19:39:07,153 ERROR libqtile manager.py:process_key_event():L390 KB command error shuffle_right: No such command
2022-02-28 19:39:25,780 ERROR libqtile manager.py:process_key_event():L390 KB command error grow_left: No such command
2022-02-28 19:39:26,116 ERROR libqtile manager.py:process_key_event():L390 KB command error grow_left: No such command
2022-02-28 19:39:26,419 ERROR libqtile manager.py:process_key_event():L390 KB command error grow_right: No such command
2022-02-28 19:39:26,668 ERROR libqtile manager.py:process_key_event():L390 KB command error grow_right: No such command
2022-02-28 19:39:27,072 ERROR libqtile manager.py:process_key_event():L390 KB command error grow_left: No such command
2022-02-28 19:39:27,295 ERROR libqtile manager.py:process_key_event():L390 KB command error grow_left: No such command
2022-02-28 19:39:27,468 ERROR libqtile manager.py:process_key_event():L390 KB command error grow_left: No such command
2022-02-28 19:39:27,649 ERROR libqtile manager.py:process_key_event():L390 KB command error grow_up: No such command
2022-02-28 19:39:28,012 ERROR libqtile manager.py:process_key_event():L390 KB command error grow_down: No such command
2022-02-28 19:39:28,242 ERROR libqtile manager.py:process_key_event():L390 KB command error grow_left: No such command
2022-02-28 19:39:28,636 ERROR libqtile manager.py:process_key_event():L390 KB command error grow_right: No such command
2022-02-28 19:39:28,908 ERROR libqtile manager.py:process_key_event():L390 KB command error grow_up: No such command
2022-02-28 19:39:29,149 ERROR libqtile manager.py:process_key_event():L390 KB command error grow_left: No such command
2022-02-28 19:39:29,436 ERROR libqtile manager.py:process_key_event():L390 KB command error grow_down: No such command
2022-02-28 19:39:29,681 ERROR libqtile manager.py:process_key_event():L390 KB command error grow_right: No such command
2022-02-28 19:39:29,942 ERROR libqtile manager.py:process_key_event():L390 KB command error grow_up: No such command
2022-02-28 19:39:30,168 ERROR libqtile manager.py:process_key_event():L390 KB command error grow_left: No such command
2022-02-28 19:39:30,455 ERROR libqtile manager.py:process_key_event():L390 KB command error grow_down: No such command
2022-02-28 19:39:30,680 ERROR libqtile manager.py:process_key_event():L390 KB command error grow_right: No such command
2022-02-28 19:39:30,936 ERROR libqtile manager.py:process_key_event():L390 KB command error grow_up: No such command
2022-02-28 19:39:31,167 ERROR libqtile manager.py:process_key_event():L390 KB command error grow_left: No such command
2022-02-28 19:39:31,455 ERROR libqtile manager.py:process_key_event():L390 KB command error grow_right: No such command
2022-02-28 19:39:31,794 ERROR libqtile manager.py:process_key_event():L390 KB command error grow_up: No such command
2022-02-28 19:39:32,022 ERROR libqtile manager.py:process_key_event():L390 KB command error grow_left: No such command
2022-02-28 19:41:12,793 WARNING libqtile lifecycle.py:_atexit():L34 Restarting Qtile with os.execv(...)
2022-02-28 19:41:38,867 WARNING libqtile lifecycle.py:_atexit():L34 Restarting Qtile with os.execv(...)
2022-02-28 19:41:41,504 WARNING libqtile lifecycle.py:_atexit():L34 Restarting Qtile with os.execv(...)
2022-02-28 19:43:18,640 WARNING libqtile lifecycle.py:_atexit():L34 Restarting Qtile with os.execv(...)
2022-02-28 19:43:18,829 WARNING libqtile utils.py:send_notification():L242 dbus-next is not installed. Unable to send notifications.
2022-02-28 19:43:18,844 ERROR libqtile group.py:layout():L121 No such layout: monadtall
2022-02-28 19:43:18,845 ERROR libqtile group.py:layout():L121 No such layout: monadtall
2022-02-28 19:43:18,846 ERROR libqtile group.py:layout():L121 No such layout: monadtall
2022-02-28 19:43:18,846 ERROR libqtile group.py:layout():L121 No such layout: monadtall
2022-02-28 19:43:18,846 ERROR libqtile group.py:layout():L121 No such layout: monadtall
2022-02-28 19:43:18,846 ERROR libqtile group.py:layout():L121 No such layout: monadtall
2022-02-28 19:43:18,847 ERROR libqtile group.py:layout():L121 No such layout: monadtall
2022-02-28 19:43:18,847 ERROR libqtile group.py:layout():L121 No such layout: monadtall
2022-02-28 19:43:18,847 ERROR libqtile group.py:layout():L121 No such layout: monadtall
2022-02-28 19:43:21,959 ERROR libqtile manager.py:cmd_reload_config():L258 Configuration error: name 'modkey' is not defined
2022-02-28 19:43:21,959 WARNING libqtile utils.py:send_notification():L242 dbus-next is not installed. Unable to send notifications.
2022-02-28 19:43:28,746 ERROR libqtile manager.py:process_button_click():L708 Mouse command error get_position: No object window in path 'window'
2022-02-28 19:56:55,780 ERROR libqtile hook.py:fire():L392 Error in hook client_name_updated
Traceback (most recent call last):
  File "/usr/lib/python3.10/site-packages/libqtile/hook.py", line 390, in fire
    i(*args, **kwargs)
  File "/usr/lib/python3.10/site-packages/libqtile/widget/windowtabs.py", line 81, in update
    self.text = self.separator.join(names)
  File "/usr/lib/python3.10/site-packages/libqtile/widget/base.py", line 396, in text
    self.layout.text = self.formatted_text
  File "/usr/lib/python3.10/site-packages/libqtile/drawer.py", line 72, in text
    attrlist, value, accel_char = pangocffi.parse_markup(value)
  File "/usr/lib/python3.10/site-packages/libqtile/pangocffi.py", line 186, in parse_markup
    raise Exception("parse_markup() failed for %s" % value)
Exception: parse_markup() failed for b'<b>Screen tearing in Firefox fullscreen Youtube videos - Graphics & Display - Manjaro Linux Forum - Brave</b>'
2022-02-28 19:56:55,780 ERROR libqtile hook.py:fire():L392 Error in hook client_name_updated
Traceback (most recent call last):
  File "/usr/lib/python3.10/site-packages/libqtile/hook.py", line 390, in fire
    i(*args, **kwargs)
  File "/usr/lib/python3.10/site-packages/libqtile/widget/windowtabs.py", line 81, in update
    self.text = self.separator.join(names)
  File "/usr/lib/python3.10/site-packages/libqtile/widget/base.py", line 396, in text
    self.layout.text = self.formatted_text
  File "/usr/lib/python3.10/site-packages/libqtile/drawer.py", line 72, in text
    attrlist, value, accel_char = pangocffi.parse_markup(value)
  File "/usr/lib/python3.10/site-packages/libqtile/pangocffi.py", line 186, in parse_markup
    raise Exception("parse_markup() failed for %s" % value)
Exception: parse_markup() failed for b'<b>Screen tearing in Firefox fullscreen Youtube videos - Graphics & Display - Manjaro Linux Forum - Brave</b>'
2022-02-28 19:56:56,200 ERROR libqtile hook.py:fire():L392 Error in hook client_name_updated
Traceback (most recent call last):
  File "/usr/lib/python3.10/site-packages/libqtile/hook.py", line 390, in fire
    i(*args, **kwargs)
  File "/usr/lib/python3.10/site-packages/libqtile/widget/windowtabs.py", line 81, in update
    self.text = self.separator.join(names)
  File "/usr/lib/python3.10/site-packages/libqtile/widget/base.py", line 396, in text
    self.layout.text = self.formatted_text
  File "/usr/lib/python3.10/site-packages/libqtile/drawer.py", line 72, in text
    attrlist, value, accel_char = pangocffi.parse_markup(value)
  File "/usr/lib/python3.10/site-packages/libqtile/pangocffi.py", line 186, in parse_markup
    raise Exception("parse_markup() failed for %s" % value)
Exception: parse_markup() failed for b'<b>Screen tearing in Firefox fullscreen Youtube videos - Support / Graphics & Display - Manjaro Linux Forum - Brave</b>'
2022-02-28 19:56:56,201 ERROR libqtile hook.py:fire():L392 Error in hook client_name_updated
Traceback (most recent call last):
  File "/usr/lib/python3.10/site-packages/libqtile/hook.py", line 390, in fire
    i(*args, **kwargs)
  File "/usr/lib/python3.10/site-packages/libqtile/widget/windowtabs.py", line 81, in update
    self.text = self.separator.join(names)
  File "/usr/lib/python3.10/site-packages/libqtile/widget/base.py", line 396, in text
    self.layout.text = self.formatted_text
  File "/usr/lib/python3.10/site-packages/libqtile/drawer.py", line 72, in text
    attrlist, value, accel_char = pangocffi.parse_markup(value)
  File "/usr/lib/python3.10/site-packages/libqtile/pangocffi.py", line 186, in parse_markup
    raise Exception("parse_markup() failed for %s" % value)
Exception: parse_markup() failed for b'<b>Screen tearing in Firefox fullscreen Youtube videos - Support / Graphics & Display - Manjaro Linux Forum - Brave</b>'
2022-02-28 19:57:02,098 ERROR libqtile hook.py:fire():L392 Error in hook focus_change
Traceback (most recent call last):
  File "/usr/lib/python3.10/site-packages/libqtile/hook.py", line 390, in fire
    i(*args, **kwargs)
  File "/usr/lib/python3.10/site-packages/libqtile/widget/windowtabs.py", line 81, in update
    self.text = self.separator.join(names)
  File "/usr/lib/python3.10/site-packages/libqtile/widget/base.py", line 396, in text
    self.layout.text = self.formatted_text
  File "/usr/lib/python3.10/site-packages/libqtile/drawer.py", line 72, in text
    attrlist, value, accel_char = pangocffi.parse_markup(value)
  File "/usr/lib/python3.10/site-packages/libqtile/pangocffi.py", line 186, in parse_markup
    raise Exception("parse_markup() failed for %s" % value)
Exception: parse_markup() failed for b'<b>Screen tearing in Firefox fullscreen Youtube videos - Support / Graphics & Display - Manjaro Linux Forum - Brave</b>'
2022-02-28 19:57:02,110 ERROR libqtile hook.py:fire():L392 Error in hook focus_change
Traceback (most recent call last):
  File "/usr/lib/python3.10/site-packages/libqtile/hook.py", line 390, in fire
    i(*args, **kwargs)
  File "/usr/lib/python3.10/site-packages/libqtile/widget/windowtabs.py", line 81, in update
    self.text = self.separator.join(names)
  File "/usr/lib/python3.10/site-packages/libqtile/widget/base.py", line 396, in text
    self.layout.text = self.formatted_text
  File "/usr/lib/python3.10/site-packages/libqtile/drawer.py", line 72, in text
    attrlist, value, accel_char = pangocffi.parse_markup(value)
  File "/usr/lib/python3.10/site-packages/libqtile/pangocffi.py", line 186, in parse_markup
    raise Exception("parse_markup() failed for %s" % value)
Exception: parse_markup() failed for b'<b>Screen tearing in Firefox fullscreen Youtube videos - Support / Graphics & Display - Manjaro Linux Forum - Brave</b>'
2022-02-28 19:57:02,183 ERROR libqtile hook.py:fire():L392 Error in hook focus_change
Traceback (most recent call last):
  File "/usr/lib/python3.10/site-packages/libqtile/hook.py", line 390, in fire
    i(*args, **kwargs)
  File "/usr/lib/python3.10/site-packages/libqtile/widget/windowtabs.py", line 81, in update
    self.text = self.separator.join(names)
  File "/usr/lib/python3.10/site-packages/libqtile/widget/base.py", line 396, in text
    self.layout.text = self.formatted_text
  File "/usr/lib/python3.10/site-packages/libqtile/drawer.py", line 72, in text
    attrlist, value, accel_char = pangocffi.parse_markup(value)
  File "/usr/lib/python3.10/site-packages/libqtile/pangocffi.py", line 186, in parse_markup
    raise Exception("parse_markup() failed for %s" % value)
Exception: parse_markup() failed for b'<b>Screen tearing in Firefox fullscreen Youtube videos - Support / Graphics & Display - Manjaro Linux Forum - Brave</b>'
2022-02-28 19:57:03,091 ERROR libqtile hook.py:fire():L392 Error in hook focus_change
Traceback (most recent call last):
  File "/usr/lib/python3.10/site-packages/libqtile/hook.py", line 390, in fire
    i(*args, **kwargs)
  File "/usr/lib/python3.10/site-packages/libqtile/widget/windowtabs.py", line 81, in update
    self.text = self.separator.join(names)
  File "/usr/lib/python3.10/site-packages/libqtile/widget/base.py", line 396, in text
    self.layout.text = self.formatted_text
  File "/usr/lib/python3.10/site-packages/libqtile/drawer.py", line 72, in text
    attrlist, value, accel_char = pangocffi.parse_markup(value)
  File "/usr/lib/python3.10/site-packages/libqtile/pangocffi.py", line 186, in parse_markup
    raise Exception("parse_markup() failed for %s" % value)
Exception: parse_markup() failed for b'<b>Screen tearing in Firefox fullscreen Youtube videos - Support / Graphics & Display - Manjaro Linux Forum - Brave</b>'
2022-02-28 19:57:04,586 ERROR libqtile hook.py:fire():L392 Error in hook client_name_updated
Traceback (most recent call last):
  File "/usr/lib/python3.10/site-packages/libqtile/hook.py", line 390, in fire
    i(*args, **kwargs)
  File "/usr/lib/python3.10/site-packages/libqtile/widget/windowtabs.py", line 81, in update
    self.text = self.separator.join(names)
  File "/usr/lib/python3.10/site-packages/libqtile/widget/base.py", line 396, in text
    self.layout.text = self.formatted_text
  File "/usr/lib/python3.10/site-packages/libqtile/drawer.py", line 72, in text
    attrlist, value, accel_char = pangocffi.parse_markup(value)
  File "/usr/lib/python3.10/site-packages/libqtile/pangocffi.py", line 186, in parse_markup
    raise Exception("parse_markup() failed for %s" % value)
Exception: parse_markup() failed for b'<b>Screen tearing in Firefox fullscreen Youtube videos - Support / Graphics & Display - Manjaro Linux Forum - Brave</b>'
2022-02-28 19:57:04,586 ERROR libqtile hook.py:fire():L392 Error in hook client_name_updated
Traceback (most recent call last):
  File "/usr/lib/python3.10/site-packages/libqtile/hook.py", line 390, in fire
    i(*args, **kwargs)
  File "/usr/lib/python3.10/site-packages/libqtile/widget/windowtabs.py", line 81, in update
    self.text = self.separator.join(names)
  File "/usr/lib/python3.10/site-packages/libqtile/widget/base.py", line 396, in text
    self.layout.text = self.formatted_text
  File "/usr/lib/python3.10/site-packages/libqtile/drawer.py", line 72, in text
    attrlist, value, accel_char = pangocffi.parse_markup(value)
  File "/usr/lib/python3.10/site-packages/libqtile/pangocffi.py", line 186, in parse_markup
    raise Exception("parse_markup() failed for %s" % value)
Exception: parse_markup() failed for b'<b>Screen tearing in Firefox fullscreen Youtube videos - Support / Graphics & Display - Manjaro Linux Forum - Brave</b>'
2022-02-28 19:57:08,596 ERROR libqtile hook.py:fire():L392 Error in hook focus_change
Traceback (most recent call last):
  File "/usr/lib/python3.10/site-packages/libqtile/hook.py", line 390, in fire
    i(*args, **kwargs)
  File "/usr/lib/python3.10/site-packages/libqtile/widget/windowtabs.py", line 81, in update
    self.text = self.separator.join(names)
  File "/usr/lib/python3.10/site-packages/libqtile/widget/base.py", line 396, in text
    self.layout.text = self.formatted_text
  File "/usr/lib/python3.10/site-packages/libqtile/drawer.py", line 72, in text
    attrlist, value, accel_char = pangocffi.parse_markup(value)
  File "/usr/lib/python3.10/site-packages/libqtile/pangocffi.py", line 186, in parse_markup
    raise Exception("parse_markup() failed for %s" % value)
Exception: parse_markup() failed for b'<b>Screen tearing in Firefox fullscreen Youtube videos - Support / Graphics & Display - Manjaro Linux Forum - Brave</b>'
2022-02-28 19:57:08,643 ERROR libqtile hook.py:fire():L392 Error in hook focus_change
Traceback (most recent call last):
  File "/usr/lib/python3.10/site-packages/libqtile/hook.py", line 390, in fire
    i(*args, **kwargs)
  File "/usr/lib/python3.10/site-packages/libqtile/widget/windowtabs.py", line 81, in update
    self.text = self.separator.join(names)
  File "/usr/lib/python3.10/site-packages/libqtile/widget/base.py", line 396, in text
    self.layout.text = self.formatted_text
  File "/usr/lib/python3.10/site-packages/libqtile/drawer.py", line 72, in text
    attrlist, value, accel_char = pangocffi.parse_markup(value)
  File "/usr/lib/python3.10/site-packages/libqtile/pangocffi.py", line 186, in parse_markup
    raise Exception("parse_markup() failed for %s" % value)
Exception: parse_markup() failed for b'<b>Screen tearing in Firefox fullscreen Youtube videos - Support / Graphics & Display - Manjaro Linux Forum - Brave</b>'
2022-02-28 19:57:12,327 ERROR libqtile hook.py:fire():L392 Error in hook focus_change
Traceback (most recent call last):
  File "/usr/lib/python3.10/site-packages/libqtile/hook.py", line 390, in fire
    i(*args, **kwargs)
  File "/usr/lib/python3.10/site-packages/libqtile/widget/windowtabs.py", line 81, in update
    self.text = self.separator.join(names)
  File "/usr/lib/python3.10/site-packages/libqtile/widget/base.py", line 396, in text
    self.layout.text = self.formatted_text
  File "/usr/lib/python3.10/site-packages/libqtile/drawer.py", line 72, in text
    attrlist, value, accel_char = pangocffi.parse_markup(value)
  File "/usr/lib/python3.10/site-packages/libqtile/pangocffi.py", line 186, in parse_markup
    raise Exception("parse_markup() failed for %s" % value)
Exception: parse_markup() failed for b'<b>Screen tearing in Firefox fullscreen Youtube videos - Support / Graphics & Display - Manjaro Linux Forum - Brave</b>'
2022-02-28 19:57:14,600 ERROR libqtile hook.py:fire():L392 Error in hook client_name_updated
Traceback (most recent call last):
  File "/usr/lib/python3.10/site-packages/libqtile/hook.py", line 390, in fire
    i(*args, **kwargs)
  File "/usr/lib/python3.10/site-packages/libqtile/widget/windowtabs.py", line 81, in update
    self.text = self.separator.join(names)
  File "/usr/lib/python3.10/site-packages/libqtile/widget/base.py", line 396, in text
    self.layout.text = self.formatted_text
  File "/usr/lib/python3.10/site-packages/libqtile/drawer.py", line 72, in text
    attrlist, value, accel_char = pangocffi.parse_markup(value)
  File "/usr/lib/python3.10/site-packages/libqtile/pangocffi.py", line 186, in parse_markup
    raise Exception("parse_markup() failed for %s" % value)
Exception: parse_markup() failed for b'<b>Screen tearing in Firefox fullscreen Youtube videos - Support / Graphics & Display - Manjaro Linux Forum - Brave</b>'
2022-02-28 19:57:14,600 ERROR libqtile hook.py:fire():L392 Error in hook client_name_updated
Traceback (most recent call last):
  File "/usr/lib/python3.10/site-packages/libqtile/hook.py", line 390, in fire
    i(*args, **kwargs)
  File "/usr/lib/python3.10/site-packages/libqtile/widget/windowtabs.py", line 81, in update
    self.text = self.separator.join(names)
  File "/usr/lib/python3.10/site-packages/libqtile/widget/base.py", line 396, in text
    self.layout.text = self.formatted_text
  File "/usr/lib/python3.10/site-packages/libqtile/drawer.py", line 72, in text
    attrlist, value, accel_char = pangocffi.parse_markup(value)
  File "/usr/lib/python3.10/site-packages/libqtile/pangocffi.py", line 186, in parse_markup
    raise Exception("parse_markup() failed for %s" % value)
Exception: parse_markup() failed for b'<b>Screen tearing in Firefox fullscreen Youtube videos - Support / Graphics & Display - Manjaro Linux Forum - Brave</b>'
2022-02-28 19:57:50,133 ERROR libqtile hook.py:fire():L392 Error in hook client_name_updated
Traceback (most recent call last):
  File "/usr/lib/python3.10/site-packages/libqtile/hook.py", line 390, in fire
    i(*args, **kwargs)
  File "/usr/lib/python3.10/site-packages/libqtile/widget/windowtabs.py", line 81, in update
    self.text = self.separator.join(names)
  File "/usr/lib/python3.10/site-packages/libqtile/widget/base.py", line 396, in text
    self.layout.text = self.formatted_text
  File "/usr/lib/python3.10/site-packages/libqtile/drawer.py", line 72, in text
    attrlist, value, accel_char = pangocffi.parse_markup(value)
  File "/usr/lib/python3.10/site-packages/libqtile/pangocffi.py", line 186, in parse_markup
    raise Exception("parse_markup() failed for %s" % value)
Exception: parse_markup() failed for b'<b>Screen tearing in Firefox fullscreen Youtube videos - Support / Graphics & Display - Manjaro Linux Forum - Brave</b>'
2022-02-28 19:57:50,134 ERROR libqtile hook.py:fire():L392 Error in hook client_name_updated
Traceback (most recent call last):
  File "/usr/lib/python3.10/site-packages/libqtile/hook.py", line 390, in fire
    i(*args, **kwargs)
  File "/usr/lib/python3.10/site-packages/libqtile/widget/windowtabs.py", line 81, in update
    self.text = self.separator.join(names)
  File "/usr/lib/python3.10/site-packages/libqtile/widget/base.py", line 396, in text
    self.layout.text = self.formatted_text
  File "/usr/lib/python3.10/site-packages/libqtile/drawer.py", line 72, in text
    attrlist, value, accel_char = pangocffi.parse_markup(value)
  File "/usr/lib/python3.10/site-packages/libqtile/pangocffi.py", line 186, in parse_markup
    raise Exception("parse_markup() failed for %s" % value)
Exception: parse_markup() failed for b'<b>Screen tearing in Firefox fullscreen Youtube videos - Support / Graphics & Display - Manjaro Linux Forum - Brave</b>'
2022-02-28 20:27:15,833 ERROR libqtile core.py:_xpoll():L331 Got an exception in poll loop
Traceback (most recent call last):
  File "/usr/lib/python3.10/site-packages/libqtile/backend/x11/core.py", line 299, in _xpoll
    ret = target(event)
  File "/usr/lib/python3.10/site-packages/libqtile/backend/x11/window.py", line 1137, in handle_KeyPress
    self.process_key_press(keysym)
  File "/usr/lib/python3.10/site-packages/libqtile/bar.py", line 508, in process_key_press
    if self.has_keyboard:
  File "/usr/lib/python3.10/site-packages/libqtile/configurable.py", line 49, in __getattr__
    raise AttributeError("%s has no attribute: %s" % (cname, name))
AttributeError: Bar has no attribute: has_keyboard
2022-02-28 20:27:15,866 ERROR libqtile core.py:_xpoll():L331 Got an exception in poll loop
Traceback (most recent call last):
  File "/usr/lib/python3.10/site-packages/libqtile/backend/x11/core.py", line 299, in _xpoll
    ret = target(event)
  File "/usr/lib/python3.10/site-packages/libqtile/backend/x11/window.py", line 1137, in handle_KeyPress
    self.process_key_press(keysym)
  File "/usr/lib/python3.10/site-packages/libqtile/bar.py", line 508, in process_key_press
    if self.has_keyboard:
  File "/usr/lib/python3.10/site-packages/libqtile/configurable.py", line 49, in __getattr__
    raise AttributeError("%s has no attribute: %s" % (cname, name))
AttributeError: Bar has no attribute: has_keyboard
2022-02-28 20:30:02,354 WARNING libqtile lifecycle.py:_atexit():L34 Restarting Qtile with os.execv(...)
2022-02-28 20:36:50,387 ERROR libqtile manager.py:process_key_event():L390 KB command error togroup: Traceback (most recent call last):
  File "/usr/lib/python3.10/site-packages/libqtile/command/interface.py", line 305, in call
    return SUCCESS, cmd(*args, **kwargs)
  File "/usr/lib/python3.10/site-packages/libqtile/backend/base.py", line 422, in cmd_togroup
    self.togroup(group_name, switch_group=switch_group)
  File "/usr/lib/python3.10/site-packages/libqtile/backend/x11/window.py", line 1528, in togroup
    self.group.remove(self)
  File "/usr/lib/python3.10/site-packages/libqtile/group.py", line 288, in remove
    self.tiled_windows.remove(win)
KeyError: Window(name='masterduel', wid=71303169)

2022-02-28 20:37:18,627 WARNING libqtile lifecycle.py:_atexit():L34 Restarting Qtile with os.execv(...)
2022-02-28 20:37:42,834 WARNING libqtile lifecycle.py:_atexit():L34 Restarting Qtile with os.execv(...)
2022-02-28 21:01:31,322 ERROR libqtile manager.py:process_key_event():L390 KB command error kill: No object window in path 'window'
2022-02-28 21:01:58,738 WARNING libqtile lifecycle.py:_atexit():L38 Qtile will now terminate
